Workbook
Name Pin_dBm: 输入配置!$C$2
Name SourceFreq: 输入配置!$C$3
Name SignalBW: 输入配置!$C$4
Name Bnoise_Hz: 输入配置!$C$5
Name Tsource_K: 输入配置!$C$6
Name Tref_K: 输入配置!$C$7
Name RequiredSNR_dB: 输入配置!$C$8
Name ImplLoss_dB: 输入配置!$C$9
Name Backoff_dB: 输入配置!$C$10
Name DefaultP: 输入配置!$C$11
Name ToneEnabled: 输入配置!$C$12
Name TonePin: 输入配置!$C$13
Name ToneSpacing: 输入配置!$C$14
Name Boltzmann: 输入配置!$C$15
Name NoiseConfigOK: 输入配置!$C$17

Sheet 使用说明
A1: RF-Link-Calculator｜可重算射频链路工作簿
A2: 构造基准A / 两级放大器
A3: 浅蓝色为可编辑输入，浅灰色为真实公式。打开Excel后请完整重算（Ctrl+Alt+F9）。
A4: openpyxl不执行公式；本文件未在本机Excel桌面重算验证。结果快照是导出时静态报告。
A5: 最多200级，第4～203行。取消隐藏空行后填写并启用；删除器件请禁用，勿删除物理行。
A6: 顺序由器件参数表的整行位置决定；整表排序/移动需包含所有列。不得单独排序某参数列。
A7: 噪声模式: manual/passive_thermal/ideal/unknown；IP3与P1: finite/ideal/unknown。
A8: IP3参考: input/output；P1参考: input/actual_output/linear_output。实际输出P1换算有额外1 dB。
A9: 不启用任何宏、插件或循环计算。压缩求解表使用82次完整链路传播（2次夹根检查＋80次二分）。
A10: JSON是标准回读格式；Excel修改不会回写网页、JSON或导出时快照。
A11: NF、IP3、P1未知分别阻断依赖指标；双音每音功率独立于主CW输入。
A12: Excel线性因子有数值范围，极端链路会显示数值域错误；Python采用对数域可覆盖更大范围。
... A17: 公式版本: 1.0.0；模型: p1_anchored_soft_saturation_v1

Sheet 输入配置
A1: 内部名称 | B1: 中文说明 | C1: 输入值 | D1: 单位
A2: Pin_dBm | B2: 主CW输入功率 | C2: -30 | D2: dBm
A3: SourceFreq | B3: 输入中心频率 | C3: 100000000 | D3: Hz
A4: SignalBW | B4: 信号带宽 | C4: 1000000 | D4: Hz
A5: Bnoise_Hz | B5: 等效噪声带宽 | C5: 1000000 | D5: Hz
A6: Tsource_K | B6: 输入源等效噪声温度 | C6: 290 | D6: K
A7: Tref_K | B7: 固定NF参考温度（勿改） | C7: 290 | D7: K
A8: RequiredSNR_dB | B8: 所需信噪比 | C8: 10 | D8: dB
A9: ImplLoss_dB | B9: 实现损失 | C9: 0 | D9: dB
A10: Backoff_dB | B10: 压缩回退 | C10: 3 | D10: dB
A11: DefaultP | B11: 默认压缩形状p | C11: 2
A12: ToneEnabled | B12: 独立双音分析启用 | C12: TRUE | D12: bool
A13: TonePin | B13: 每音输入功率 | C13: -30 | D13: dBm
A14: ToneSpacing | B14: 双音间隔 | C14: 100000 | D14: Hz
A15: Boltzmann | B15: 玻尔兹曼常数（勿改） | C15: 1.380649e-23 | D15: J/K
A17: NoiseConfigOK | B17: 噪声配置有效 | C17: =AND(ISNUMBER(Bnoise_Hz),Bnoise_Hz>0,ISNUMBER(Tsource_K),Tsource_K>0,Tref_K=290,Boltzmann=1.380649E-23) -> TRUE

Sheet 器件参数
A1: 编辑输入：最多200级；空行明确禁用，整行重排；名称与备注不会执行为公式
A3: 顺序 | B3: 启用 | C3: 器件ID | D3: 名称 | E3: 类型 | F3: 增益dB | G3: 噪声模式 | H3: NF dB | I3: 物理温度K | J3: IP3模式 | K3: IP3参考 | L3: IP3 dBm | M3: P1模式 | N3: P1参考 | O3: P1 dBm | P3: 形状p | Q3: 来源与条件 | R3: 频率下限Hz | S3: 频率上限Hz | T3: LO Hz | U3: 变频关系 | V3: NF口径 | W3: 噪声口径已确认 | X3: 最大输入dBm | Y3: 备注
A4: 1 | B4: TRUE | C4: 2f996e9f-a030-58e7-8824-f65c22788ebc | D4: 放大器A | E4: amplifier | F4: 10 | G4: manual | H4: 3 | I4: 290 | J4: finite | K4: input | L4: 10 | M4: finite | N4: input | O4: 0 | P4: 2 | Q4: {'kind': 'synthetic_example', 'note': '构造演示值，不代表实测或任何厂商'} | W4: FALSE
A5: 2 | B5: TRUE | C5: 0ed06258-f7fd-5875-b34b-17563dee4380 | D5: 放大器B | E5: amplifier | F5: 10 | G5: manual | H5: 6 | I5: 290 | J5: finite | K5: input | L5: 20 | M5: finite | N5: input | O5: 5 | P5: 2 | Q5: {'kind': 'synthetic_example', 'note': '构造演示值，不代表实测或任何厂商'} | W5: FALSE
A6: 3 | B6: FALSE | C6: reserved-3 | E6: custom | G6: unknown | I6: 290 | J6: unknown | K6: input | M6: unknown | N6: input | V6: unknown | W6: FALSE
A7: 4 | B7: FALSE | C7: reserved-4 | E7: custom | G7: unknown | I7: 290 | J7: unknown | K7: input | M7: unknown | N7: input | V7: unknown | W7: FALSE
A8: 5 | B8: FALSE | C8: reserved-5 | E8: custom | G8: unknown | I8: 290 | J8: unknown | K8: input | M8: unknown | N8: input | V8: unknown | W8: FALSE
A9: 6 | B9: FALSE | C9: reserved-6 | E9: custom | G9: unknown | I9: 290 | J9: unknown | K9: input | M9: unknown | N9: input | V9: unknown | W9: FALSE
A10: 7 | B10: FALSE | C10: reserved-7 | E10: custom | G10: unknown | I10: 290 | J10: unknown | K10: input | M10: unknown | N10: input | V10: unknown | W10: FALSE
A11: 8 | B11: FALSE | C11: reserved-8 | E11: custom | G11: unknown | I11: 290 | J11: unknown | K11: input | M11: unknown | N11: input | V11: unknown | W11: FALSE
A12: 9 | B12: FALSE | C12: reserved-9 | E12: custom | G12: unknown | I12: 290 | J12: unknown | K12: input | M12: unknown | N12: input | V12: unknown | W12: FALSE
A13: 10 | B13: FALSE | C13: reserved-10 | E13: custom | G13: unknown | I13: 290 | J13: unknown | K13: input | M13: unknown | N13: input | V13: unknown | W13: FALSE
A14: 11 | B14: FALSE | C14: reserved-11 | E14: custom | G14: unknown | I14: 290 | J14: unknown | K14: input | M14: unknown | N14: input | V14: unknown | W14: FALSE
A15: 12 | B15: FALSE | C15: reserved-12 | E15: custom | G15: unknown | I15: 290 | J15: unknown | K15: input | M15: unknown | N15: input | V15: unknown | W15: FALSE
A16: 13 | B16: FALSE | C16: reserved-13 | E16: custom | G16: unknown | I16: 290 | J16: unknown | K16: input | M16: unknown | N16: input | V16: unknown | W16: FALSE
A17: 14 | B17: FALSE | C17: reserved-14 | E17: custom | G17: unknown | I17: 290 | J17: unknown | K17: input | M17: unknown | N17: input | V17: unknown | W17: FALSE
... A203: 200 | B203: FALSE | C203: reserved-200 | E203: custom | G203: unknown | I203: 290 | J203: unknown | K203: input | M203: unknown | N203: input | V203: unknown | W203: FALSE

Sheet 逐级计算
A1: 当前Excel公式结果（自动重算）｜压缩为模型估算｜噪声为小信号预算
A2: 顺序 | B2: 器件名称 | C2: 有效增益dB | D2: 前级增益dB | E2: 累计增益dB | F2: 前级线性增益 | G2: 本级噪声因子 | H2: 累计噪声因子 | I2: 累计NF dB | J2: 线性输入dBm | K2: 线性输出dBm | L2: 本级IIP3 dBm | M2: IP3倒数和 | N2: 累计IIP3 dBm | O2: 累计OIP3 dBm | P2: 本级输入P1 dBm | Q2: 有效p | R2: 估算输入dBm | S2: 稳定指数z | T2: 本级压缩dB | U2: 估算输出dBm | V2: 累计压缩dB | W2: 入口折算阈值dBm | X2: 压缩模式 -1未知/0理想/1有限 | Y2: 噪声状态 | Z2: IP3状态 | AA2: 压缩状态 | AB2: 输入频率Hz | AC2: 输出频率Hz | AD2: 本级NF dB | AE2: 输入温度贡献K | AF2: 输出噪声dBm | AG2: SNR dB | AH2: 每音输出dBm | AI2: 弱非线性IM3外推dBm | AJ2: 有限级p | AK2: 频率适用性 | AL2: 同p闭式项 | AM2: 额定告警 | AN2: 基波1 Hz | AO2: 基波2 Hz | AP2: IM3低侧Hz | AQ2: IM3高侧Hz | AR2: 双音通带条件
E3: 0 | H3: 1 | M3: 0 | U3: =Pin_dBm -> -30 | AC3: =SourceFreq -> 100000000 | AN3: =SourceFreq+(-0.5)*ToneSpacing -> 99950000 | AO3: =SourceFreq+(0.5)*ToneSpacing -> 100050000 | AP3: =SourceFreq+(-1.5)*ToneSpacing -> 99850000 | AQ3: =SourceFreq+(1.5)*ToneSpacing -> 100150000 | AR3: =AND(MIN(AN3:AQ3)>0,ToneSpacing>0) -> TRUE
A4: =器件参数!A4 -> 1 | B4: =器件参数!D4 -> 放大器A | C4: =IF(NOT(器件参数!B4),0,IF(AND(ISNUMBER(器件参数!F4),ABS(器件参数!F4)<=300),器件参数!F4,"")) -> 10 | D4: =IF(ISNUMBER(E3),E3,"") -> 0 | E4: =IF(AND(ISNUMBER(C4),ISNUMBER(D4)),C4+D4,"") -> 10 | F4: =IFERROR(IF(AND(ISNUMBER(D4)),10^(D4/10),""),"数值域错误") -> 1 | G4: =IFERROR(IF(NOT(器件参数!B4),1,IF(NOT(OR(器件参数!E4<>"mixer",AND(OR(器件参数!V4="SSB",器件参数!V4="DSB"),器件参数!W4=TRUE))),"",IF(器件参数!G4="ideal",1,IF(AND(器件参数!G4="manual",ISNUMBER(器件参数!H4),器件参数!H4>=0),10^(器件参数!H4/10),IF(AND(器件参数!G4="passive_thermal",OR(器件参数!E4="filter_bpf",器件参数!E4="filter_lpf",器件参数!E4="filter_hpf",器件参数!E4="filter_bsf",器件参数!E4="attenuator",器件参数!E4="cable",器件参数!E4="connector",器件参数!E4="switch",器件参数!E4="isolator",器件参数!E4="coupler",器件参数!E4="splitter"),AND(ISNUMBER(器件参数!F4),ABS(器件参数!F4)<=300),器件参数!F4<=0,ISNUMBER(器件参数!I4),器件参数!I4>0),1+(10^(-器件参数!F4/10)-1)*器件参数!I4/Tref_K,""))))),"数值域错误") -> 1.9952623 | H4: =IFERROR(IF(AND(ISNUMBER(H3),ISNUMBER(G4),ISNUMBER(F4)),H3+(G4-1)/F4,""),"数值域错误") -> 1.9952623 | I4: =IF(AND(ISNUMBER(H4)),10*LOG10(H4),"") -> 3 | J4: =IF(AND(ISNUMBER(Pin_dBm),ISNUMBER(D4)),Pin_dBm+D4,"") -> -30 | K4: =IF(AND(ISNUMBER(Pin_dBm),ISNUMBER(E4)),Pin_dBm+E4,"") -> -20 | L4: =IF(AND(器件参数!J4="finite",ISNUMBER(器件参数!L4),ISNUMBER(C4)),IF(器件参数!K4="input",器件参数!L4,IF(器件参数!K4="output",器件参数!L4-C4,"")),"") -> 10 | M4: =IFERROR(IF(NOT(ISNUMBER(M3)),"",IF(OR(NOT(器件参数!B4),器件参数!J4="ideal"),M3,IF(AND(ISNUMBER(L4),ISNUMBER(F4)),M3+F4/10^(L4/10),""))),"数值域错误") -> 0.1 | N4: =IF(AND(ISNUMBER(M4),M4>0),-10*LOG10(M4),"") -> 10 | O4: =IF(AND(ISNUMBER(N4),ISNUMBER(E4)),N4+E4,"") -> 20 | P4: =IF(AND(器件参数!M4="finite",ISNUMBER(器件参数!O4),ISNUMBER(C4)),IF(器件参数!N4="input",器件参数!O4,IF(器件参数!N4="actual_output",器件参数!O4-C4+1,IF(器件参数!N4="linear_output",器件参数!O4-C4,""))),"") -> 0 | Q4: =IF(器件参数!P4="",IF(AND(ISNUMBER(DefaultP),DefaultP>=1,DefaultP<=10),DefaultP,""),IF(AND(ISNUMBER(器件参数!P4),器件参数!P4>=1,器件参数!P4<=10),器件参数!P4,"")) -> 2 | R4: =IF(ISNUMBER(U3),U3,"") -> -30 | S4: =IF(AND(ISNUMBER(Q4),ISNUMBER(R4),ISNUMBER(P4)),LN(10^(Q4/10)-1)+Q4*(R4-P4)*LN(10)/10,"") -> -14.351837 | T4: =IF(X4=0,0,IF(AND(X4=1,ISNUMBER(S4)),10/(Q4*LN(10))*(MAX(S4,0)+LN(1+EXP(-ABS(S4)))),"")) -> 1.2700791e-06 | U4: =IF(AND(ISNUMBER(R4),ISNUMBER(C4),ISNUMBER(T4)),R4+C4-T4,"") -> -20.000001 | V4: =IF(AND(ISNUMBER(Pin_dBm),ISNUMBER(E4),ISNUMBER(U4)),Pin_dBm+E4-U4,"") -> 1.2700791e-06 | W4: =IF(AND(器件参数!B4,X4=1,ISNUMBER(D4)),P4-D4,"") -> 0 | X4: =IF(NOT(ISNUMBER(C4)),-1,IF(OR(NOT(器件参数!B4),器件参数!M4="ideal"),0,IF(AND(ISNUMBER(P4),ISNUMBER(Q4)),1,-1))) -> 1 | Y4: =IF(ISNUMBER(H4),"有效","未知／噪声参数或口径不完整") -> 有效 | Z4: =IF(NOT(ISNUMBER(M4)),"未知／IP3参数不完整",IF(M4=0,"理想／无有限值","有效")) -> 有效 | AA4: =IF(ISNUMBER(U4),"模型估算","未知／增益或压缩参数不完整") -> 模型估算 | AB4: =IF(ISNUMBER(AC3),AC3,"") -> 100000000 | AC4: =IF(NOT(ISNUMBER(AB4)),"",IF(OR(NOT(器件参数!B4),器件参数!E4<>"mixer"),AB4,IF(AND(ISNUMBER(器件参数!T4),器件参数!T4>0),IF(器件参数!U4="sum",AB4+器件参数!T4,IF(器件参数!U4="difference",ABS(AB4-器件参数!T4),"")),""))) -> 100000000 | AD4: =IF(AND(ISNUMBER(G4)),10*LOG10(G4),"") -> 3 | AE4: =IF(AND(ISNUMBER(G4),ISNUMBER(F4)),Tref_K*(G4-1)/F4,"") -> 288.62607 | AF4: =IF(AND(ISNUMBER(H4),ISNUMBER(E4),NoiseConfigOK),10*LOG10(Boltzmann*Bnoise_Hz*(Tsource_K+Tref_K*(H4-1)))+30+E4,"") -> -100.97519 | AG4: =IF(AND(ISNUMBER(K4),ISNUMBER(AF4)),K4-AF4,"") -> 80.975187 | AH4: =IF(AND(ToneEnabled,ISNUMBER(E4),ISNUMBER(TonePin)),TonePin+E4,"") -> -20 | AI4: =IF(AND(ToneEnabled,ISNUMBER(E4),ISNUMBER(N4),ISNUMBER(TonePin)),3*TonePin+E4-2*N4,"") -> -100 | AJ4: =IF(X4=1,Q4,"") -> 2 | AK4: =IF(NOT(器件参数!B4),"旁路",IF(NOT(ISNUMBER(AC4)),"频率未知",IF(AC4<=SignalBW/2,"跨零频",IF(AND(ISNUMBER(器件参数!R4),ISNUMBER(器件参数!S4)),IF(AND(AB4-SignalBW/2>=器件参数!R4,AB4+SignalBW/2<=器件参数!S4),"有效","超声明通带"),"未声明通带")))) -> 未声明通带 | AL4: =IFERROR(IF(AND(X4=1,ISNUMBER(D4)),10^(Q4*(D4-P4)/10),0),"数值域错误") -> 1 | AM4: =IF(AND(器件参数!B4,ISNUMBER(器件参数!X4),OR(AND(ISNUMBER(J4),J4>器件参数!X4),IF(AND(ToneEnabled,ISNUMBER(TonePin),ISNUMBER(D4)),TonePin+10*LOG10(2)+D4>器件参数!X4,FALSE))),"超过绝对最大输入额定值","") | AN4: =IF(NOT(ISNUMBER(AN3)),"",IF(OR(NOT(器件参数!B4),器件参数!E4<>"mixer"),AN3,IF(AND(ISNUMBER(器件参数!T4),器件参数!T4>0),IF(器件参数!U4="sum",AN3+器件参数!T4,ABS(AN3-器件参数!T4)),""))) -> 99950000 | AO4: =IF(NOT(ISNUMBER(AO3)),"",IF(OR(NOT(器件参数!B4),器件参数!E4<>"mixer"),AO3,IF(AND(ISNUMBER(器件参数!T4),器件参数!T4>0),IF(器件参数!U4="sum",AO3+器件参数!T4,ABS(AO3-器件参数!T4)),""))) -> 100050000 | AP4: =IF(NOT(ISNUMBER(AP3)),"",IF(OR(NOT(器件参数!B4),器件参数!E4<>"mixer"),AP3,IF(AND(ISNUMBER(器件参数!T4),器件参数!T4>0),IF(器件参数!U4="sum",AP3+器件参数!T4,ABS(AP3-器件参数!T4)),""))) -> 99850000 | AQ4: =IF(NOT(ISNUMBER(AQ3)),"",IF(OR(NOT(器件参数!B4),器件参数!E4<>"mixer"),AQ3,IF(AND(ISNUMBER(器件参数!T4),器件参数!T4>0),IF(器件参数!U4="sum",AQ3+器件参数!T4,ABS(AQ3-器件参数!T4)),""))) -> 100150000 | AR4: =IF(NOT(AR3),FALSE,IF(NOT(器件参数!B4),TRUE,AND(COUNT(AN4:AQ4)=4,MIN(AN4:AQ4)>0,IF(AND(ISNUMBER(器件参数!R4),ISNUMBER(器件参数!S4)),AND(MIN(AN3:AQ3)>=器件参数!R4,MAX(AN3:AQ3)<=器件参数!S4),TRUE),IF(AND(器件参数!E4="mixer",器件参数!U4="difference"),OR(器件参数!T4<MIN(AN3:AQ3),器件参数!T4>MAX(AN3:AQ3)),TRUE)))) -> TRUE
A5: =器件参数!A5 -> 2 | B5: =器件参数!D5 -> 放大器B | C5: =IF(NOT(器件参数!B5),0,IF(AND(ISNUMBER(器件参数!F5),ABS(器件参数!F5)<=300),器件参数!F5,"")) -> 10 | D5: =IF(ISNUMBER(E4),E4,"") -> 10 | E5: =IF(AND(ISNUMBER(C5),ISNUMBER(D5)),C5+D5,"") -> 20 | F5: =IFERROR(IF(AND(ISNUMBER(D5)),10^(D5/10),""),"数值域错误") -> 10 | G5: =IFERROR(IF(NOT(器件参数!B5),1,IF(NOT(OR(器件参数!E5<>"mixer",AND(OR(器件参数!V5="SSB",器件参数!V5="DSB"),器件参数!W5=TRUE))),"",IF(器件参数!G5="ideal",1,IF(AND(器件参数!G5="manual",ISNUMBER(器件参数!H5),器件参数!H5>=0),10^(器件参数!H5/10),IF(AND(器件参数!G5="passive_thermal",OR(器件参数!E5="filter_bpf",器件参数!E5="filter_lpf",器件参数!E5="filter_hpf",器件参数!E5="filter_bsf",器件参数!E5="attenuator",器件参数!E5="cable",器件参数!E5="connector",器件参数!E5="switch",器件参数!E5="isolator",器件参数!E5="coupler",器件参数!E5="splitter"),AND(ISNUMBER(器件参数!F5),ABS(器件参数!F5)<=300),器件参数!F5<=0,ISNUMBER(器件参数!I5),器件参数!I5>0),1+(10^(-器件参数!F5/10)-1)*器件参数!I5/Tref_K,""))))),"数值域错误") -> 3.9810717 | H5: =IFERROR(IF(AND(ISNUMBER(H4),ISNUMBER(G5),ISNUMBER(F5)),H4+(G5-1)/F5,""),"数值域错误") -> 2.2933695 | I5: =IF(AND(ISNUMBER(H5)),10*LOG10(H5),"") -> 3.6047403 | J5: =IF(AND(ISNUMBER(Pin_dBm),ISNUMBER(D5)),Pin_dBm+D5,"") -> -20 | K5: =IF(AND(ISNUMBER(Pin_dBm),ISNUMBER(E5)),Pin_dBm+E5,"") -> -10 | L5: =IF(AND(器件参数!J5="finite",ISNUMBER(器件参数!L5),ISNUMBER(C5)),IF(器件参数!K5="input",器件参数!L5,IF(器件参数!K5="output",器件参数!L5-C5,"")),"") -> 20 | M5: =IFERROR(IF(NOT(ISNUMBER(M4)),"",IF(OR(NOT(器件参数!B5),器件参数!J5="ideal"),M4,IF(AND(ISNUMBER(L5),ISNUMBER(F5)),M4+F5/10^(L5/10),""))),"数值域错误") -> 0.2 | N5: =IF(AND(ISNUMBER(M5),M5>0),-10*LOG10(M5),"") -> 6.9897 | O5: =IF(AND(ISNUMBER(N5),ISNUMBER(E5)),N5+E5,"") -> 26.9897 | P5: =IF(AND(器件参数!M5="finite",ISNUMBER(器件参数!O5),ISNUMBER(C5)),IF(器件参数!N5="input",器件参数!O5,IF(器件参数!N5="actual_output",器件参数!O5-C5+1,IF(器件参数!N5="linear_output",器件参数!O5-C5,""))),"") -> 5 | Q5: =IF(器件参数!P5="",IF(AND(ISNUMBER(DefaultP),DefaultP>=1,DefaultP<=10),DefaultP,""),IF(AND(ISNUMBER(器件参数!P5),器件参数!P5>=1,器件参数!P5<=10),器件参数!P5,"")) -> 2 | R5: =IF(ISNUMBER(U4),U4,"") -> -20.000001 | S5: =IF(AND(ISNUMBER(Q5),ISNUMBER(R5),ISNUMBER(P5)),LN(10^(Q5/10)-1)+Q5*(R5-P5)*LN(10)/10,"") -> -12.049252 | T5: =IF(X5=0,0,IF(AND(X5=1,ISNUMBER(S5)),10/(Q5*LN(10))*(MAX(S5,0)+LN(1+EXP(-ABS(S5)))),"")) -> 1.270075e-05 | U5: =IF(AND(ISNUMBER(R5),ISNUMBER(C5),ISNUMBER(T5)),R5+C5-T5,"") -> -10.000014 | V5: =IF(AND(ISNUMBER(Pin_dBm),ISNUMBER(E5),ISNUMBER(U5)),Pin_dBm+E5-U5,"") -> 1.3970829e-05 | W5: =IF(AND(器件参数!B5,X5=1,ISNUMBER(D5)),P5-D5,"") -> -5 | X5: =IF(NOT(ISNUMBER(C5)),-1,IF(OR(NOT(器件参数!B5),器件参数!M5="ideal"),0,IF(AND(ISNUMBER(P5),ISNUMBER(Q5)),1,-1))) -> 1 | Y5: =IF(ISNUMBER(H5),"有效","未知／噪声参数或口径不完整") -> 有效 | Z5: =IF(NOT(ISNUMBER(M5)),"未知／IP3参数不完整",IF(M5=0,"理想／无有限值","有效")) -> 有效 | AA5: =IF(ISNUMBER(U5),"模型估算","未知／增益或压缩参数不完整") -> 模型估算 | AB5: =IF(ISNUMBER(AC4),AC4,"") -> 100000000 | AC5: =IF(NOT(ISNUMBER(AB5)),"",IF(OR(NOT(器件参数!B5),器件参数!E5<>"mixer"),AB5,IF(AND(ISNUMBER(器件参数!T5),器件参数!T5>0),IF(器件参数!U5="sum",AB5+器件参数!T5,IF(器件参数!U5="difference",ABS(AB5-器件参数!T5),"")),""))) -> 100000000 | AD5: =IF(AND(ISNUMBER(G5)),10*LOG10(G5),"") -> 6 | AE5: =IF(AND(ISNUMBER(G5),ISNUMBER(F5)),Tref_K*(G5-1)/F5,"") -> 86.451079 | AF5: =IF(AND(ISNUMBER(H5),ISNUMBER(E5),NoiseConfigOK),10*LOG10(Boltzmann*Bnoise_Hz*(Tsource_K+Tref_K*(H5-1)))+30+E5,"") -> -90.370447 | AG5: =IF(AND(ISNUMBER(K5),ISNUMBER(AF5)),K5-AF5,"") -> 80.370447 | AH5: =IF(AND(ToneEnabled,ISNUMBER(E5),ISNUMBER(TonePin)),TonePin+E5,"") -> -10 | AI5: =IF(AND(ToneEnabled,ISNUMBER(E5),ISNUMBER(N5),ISNUMBER(TonePin)),3*TonePin+E5-2*N5,"") -> -83.9794 | AJ5: =IF(X5=1,Q5,"") -> 2 | AK5: =IF(NOT(器件参数!B5),"旁路",IF(NOT(ISNUMBER(AC5)),"频率未知",IF(AC5<=SignalBW/2,"跨零频",IF(AND(ISNUMBER(器件参数!R5),ISNUMBER(器件参数!S5)),IF(AND(AB5-SignalBW/2>=器件参数!R5,AB5+SignalBW/2<=器件参数!S5),"有效","超声明通带"),"未声明通带")))) -> 未声明通带 | AL5: =IFERROR(IF(AND(X5=1,ISNUMBER(D5)),10^(Q5*(D5-P5)/10),0),"数值域错误") -> 10 | AM5: =IF(AND(器件参数!B5,ISNUMBER(器件参数!X5),OR(AND(ISNUMBER(J5),J5>器件参数!X5),IF(AND(ToneEnabled,ISNUMBER(TonePin),ISNUMBER(D5)),TonePin+10*LOG10(2)+D5>器件参数!X5,FALSE))),"超过绝对最大输入额定值","") | AN5: =IF(NOT(ISNUMBER(AN4)),"",IF(OR(NOT(器件参数!B5),器件参数!E5<>"mixer"),AN4,IF(AND(ISNUMBER(器件参数!T5),器件参数!T5>0),IF(器件参数!U5="sum",AN4+器件参数!T5,ABS(AN4-器件参数!T5)),""))) -> 99950000 | AO5: =IF(NOT(ISNUMBER(AO4)),"",IF(OR(NOT(器件参数!B5),器件参数!E5<>"mixer"),AO4,IF(AND(ISNUMBER(器件参数!T5),器件参数!T5>0),IF(器件参数!U5="sum",AO4+器件参数!T5,ABS(AO4-器件参数!T5)),""))) -> 100050000 | AP5: =IF(NOT(ISNUMBER(AP4)),"",IF(OR(NOT(器件参数!B5),器件参数!E5<>"mixer"),AP4,IF(AND(ISNUMBER(器件参数!T5),器件参数!T5>0),IF(器件参数!U5="sum",AP4+器件参数!T5,ABS(AP4-器件参数!T5)),""))) -> 99850000 | AQ5: =IF(NOT(ISNUMBER(AQ4)),"",IF(OR(NOT(器件参数!B5),器件参数!E5<>"mixer"),AQ4,IF(AND(ISNUMBER(器件参数!T5),器件参数!T5>0),IF(器件参数!U5="sum",AQ4+器件参数!T5,ABS(AQ4-器件参数!T5)),""))) -> 100150000 | AR5: =IF(NOT(AR4),FALSE,IF(NOT(器件参数!B5),TRUE,AND(COUNT(AN5:AQ5)=4,MIN(AN5:AQ5)>0,IF(AND(ISNUMBER(器件参数!R5),ISNUMBER(器件参数!S5)),AND(MIN(AN4:AQ4)>=器件参数!R5,MAX(AN4:AQ4)<=器件参数!S5),TRUE),IF(AND(器件参数!E5="mixer",器件参数!U5="difference"),OR(器件参数!T5<MIN(AN4:AQ4),器件参数!T5>MAX(AN4:AQ4)),TRUE)))) -> TRUE
A6: =器件参数!A6 -> 3 | B6: =器件参数!D6 | C6: =IF(NOT(器件参数!B6),0,IF(AND(ISNUMBER(器件参数!F6),ABS(器件参数!F6)<=300),器件参数!F6,"")) -> 0 | D6: =IF(ISNUMBER(E5),E5,"") -> 20 | E6: =IF(AND(ISNUMBER(C6),ISNUMBER(D6)),C6+D6,"") -> 20 | F6: =IFERROR(IF(AND(ISNUMBER(D6)),10^(D6/10),""),"数值域错误") -> 100 | G6: =IFERROR(IF(NOT(器件参数!B6),1,IF(NOT(OR(器件参数!E6<>"mixer",AND(OR(器件参数!V6="SSB",器件参数!V6="DSB"),器件参数!W6=TRUE))),"",IF(器件参数!G6="ideal",1,IF(AND(器件参数!G6="manual",ISNUMBER(器件参数!H6),器件参数!H6>=0),10^(器件参数!H6/10),IF(AND(器件参数!G6="passive_thermal",OR(器件参数!E6="filter_bpf",器件参数!E6="filter_lpf",器件参数!E6="filter_hpf",器件参数!E6="filter_bsf",器件参数!E6="attenuator",器件参数!E6="cable",器件参数!E6="connector",器件参数!E6="switch",器件参数!E6="isolator",器件参数!E6="coupler",器件参数!E6="splitter"),AND(ISNUMBER(器件参数!F6),ABS(器件参数!F6)<=300),器件参数!F6<=0,ISNUMBER(器件参数!I6),器件参数!I6>0),1+(10^(-器件参数!F6/10)-1)*器件参数!I6/Tref_K,""))))),"数值域错误") -> 1 | H6: =IFERROR(IF(AND(ISNUMBER(H5),ISNUMBER(G6),ISNUMBER(F6)),H5+(G6-1)/F6,""),"数值域错误") -> 2.2933695 | I6: =IF(AND(ISNUMBER(H6)),10*LOG10(H6),"") -> 3.6047403 | J6: =IF(AND(ISNUMBER(Pin_dBm),ISNUMBER(D6)),Pin_dBm+D6,"") -> -10 | K6: =IF(AND(ISNUMBER(Pin_dBm),ISNUMBER(E6)),Pin_dBm+E6,"") -> -10 | L6: =IF(AND(器件参数!J6="finite",ISNUMBER(器件参数!L6),ISNUMBER(C6)),IF(器件参数!K6="input",器件参数!L6,IF(器件参数!K6="output",器件参数!L6-C6,"")),"") | M6: =IFERROR(IF(NOT(ISNUMBER(M5)),"",IF(OR(NOT(器件参数!B6),器件参数!J6="ideal"),M5,IF(AND(ISNUMBER(L6),ISNUMBER(F6)),M5+F6/10^(L6/10),""))),"数值域错误") -> 0.2 | N6: =IF(AND(ISNUMBER(M6),M6>0),-10*LOG10(M6),"") -> 6.9897 | O6: =IF(AND(ISNUMBER(N6),ISNUMBER(E6)),N6+E6,"") -> 26.9897 | P6: =IF(AND(器件参数!M6="finite",ISNUMBER(器件参数!O6),ISNUMBER(C6)),IF(器件参数!N6="input",器件参数!O6,IF(器件参数!N6="actual_output",器件参数!O6-C6+1,IF(器件参数!N6="linear_output",器件参数!O6-C6,""))),"") | Q6: =IF(器件参数!P6="",IF(AND(ISNUMBER(DefaultP),DefaultP>=1,DefaultP<=10),DefaultP,""),IF(AND(ISNUMBER(器件参数!P6),器件参数!P6>=1,器件参数!P6<=10),器件参数!P6,"")) -> 2 | R6: =IF(ISNUMBER(U5),U5,"") -> -10.000014 | S6: =IF(AND(ISNUMBER(Q6),ISNUMBER(R6),ISNUMBER(P6)),LN(10^(Q6/10)-1)+Q6*(R6-P6)*LN(10)/10,"") | T6: =IF(X6=0,0,IF(AND(X6=1,ISNUMBER(S6)),10/(Q6*LN(10))*(MAX(S6,0)+LN(1+EXP(-ABS(S6)))),"")) -> 0 | U6: =IF(AND(ISNUMBER(R6),ISNUMBER(C6),ISNUMBER(T6)),R6+C6-T6,"") -> -10.000014 | V6: =IF(AND(ISNUMBER(Pin_dBm),ISNUMBER(E6),ISNUMBER(U6)),Pin_dBm+E6-U6,"") -> 1.3970829e-05 | W6: =IF(AND(器件参数!B6,X6=1,ISNUMBER(D6)),P6-D6,"") | X6: =IF(NOT(ISNUMBER(C6)),-1,IF(OR(NOT(器件参数!B6),器件参数!M6="ideal"),0,IF(AND(ISNUMBER(P6),ISNUMBER(Q6)),1,-1))) -> 0 | Y6: =IF(ISNUMBER(H6),"有效","未知／噪声参数或口径不完整") -> 有效 | Z6: =IF(NOT(ISNUMBER(M6)),"未知／IP3参数不完整",IF(M6=0,"理想／无有限值","有效")) -> 有效 | AA6: =IF(ISNUMBER(U6),"模型估算","未知／增益或压缩参数不完整") -> 模型估算 | AB6: =IF(ISNUMBER(AC5),AC5,"") -> 100000000 | AC6: =IF(NOT(ISNUMBER(AB6)),"",IF(OR(NOT(器件参数!B6),器件参数!E6<>"mixer"),AB6,IF(AND(ISNUMBER(器件参数!T6),器件参数!T6>0),IF(器件参数!U6="sum",AB6+器件参数!T6,IF(器件参数!U6="difference",ABS(AB6-器件参数!T6),"")),""))) -> 100000000 | AD6: =IF(AND(ISNUMBER(G6)),10*LOG10(G6),"") -> 0 | AE6: =IF(AND(ISNUMBER(G6),ISNUMBER(F6)),Tref_K*(G6-1)/F6,"") -> 0 | AF6: =IF(AND(ISNUMBER(H6),ISNUMBER(E6),NoiseConfigOK),10*LOG10(Boltzmann*Bnoise_Hz*(Tsource_K+Tref_K*(H6-1)))+30+E6,"") -> -90.370447 | AG6: =IF(AND(ISNUMBER(K6),ISNUMBER(AF6)),K6-AF6,"") -> 80.370447 | AH6: =IF(AND(ToneEnabled,ISNUMBER(E6),ISNUMBER(TonePin)),TonePin+E6,"") -> -10 | AI6: =IF(AND(ToneEnabled,ISNUMBER(E6),ISNUMBER(N6),ISNUMBER(TonePin)),3*TonePin+E6-2*N6,"") -> -83.9794 | AJ6: =IF(X6=1,Q6,"") | AK6: =IF(NOT(器件参数!B6),"旁路",IF(NOT(ISNUMBER(AC6)),"频率未知",IF(AC6<=SignalBW/2,"跨零频",IF(AND(ISNUMBER(器件参数!R6),ISNUMBER(器件参数!S6)),IF(AND(AB6-SignalBW/2>=器件参数!R6,AB6+SignalBW/2<=器件参数!S6),"有效","超声明通带"),"未声明通带")))) -> 旁路 | AL6: =IFERROR(IF(AND(X6=1,ISNUMBER(D6)),10^(Q6*(D6-P6)/10),0),"数值域错误") -> 0 | AM6: =IF(AND(器件参数!B6,ISNUMBER(器件参数!X6),OR(AND(ISNUMBER(J6),J6>器件参数!X6),IF(AND(ToneEnabled,ISNUMBER(TonePin),ISNUMBER(D6)),TonePin+10*LOG10(2)+D6>器件参数!X6,FALSE))),"超过绝对最大输入额定值","") | AN6: =IF(NOT(ISNUMBER(AN5)),"",IF(OR(NOT(器件参数!B6),器件参数!E6<>"mixer"),AN5,IF(AND(ISNUMBER(器件参数!T6),器件参数!T6>0),IF(器件参数!U6="sum",AN5+器件参数!T6,ABS(AN5-器件参数!T6)),""))) -> 99950000 | AO6: =IF(NOT(ISNUMBER(AO5)),"",IF(OR(NOT(器件参数!B6),器件参数!E6<>"mixer"),AO5,IF(AND(ISNUMBER(器件参数!T6),器件参数!T6>0),IF(器件参数!U6="sum",AO5+器件参数!T6,ABS(AO5-器件参数!T6)),""))) -> 100050000 | AP6: =IF(NOT(ISNUMBER(AP5)),"",IF(OR(NOT(器件参数!B6),器件参数!E6<>"mixer"),AP5,IF(AND(ISNUMBER(器件参数!T6),器件参数!T6>0),IF(器件参数!U6="sum",AP5+器件参数!T6,ABS(AP5-器件参数!T6)),""))) -> 99850000 | AQ6: =IF(NOT(ISNUMBER(AQ5)),"",IF(OR(NOT(器件参数!B6),器件参数!E6<>"mixer"),AQ5,IF(AND(ISNUMBER(器件参数!T6),器件参数!T6>0),IF(器件参数!U6="sum",AQ5+器件参数!T6,ABS(AQ5-器件参数!T6)),""))) -> 100150000 | AR6: =IF(NOT(AR5),FALSE,IF(NOT(器件参数!B6),TRUE,AND(COUNT(AN6:AQ6)=4,MIN(AN6:AQ6)>0,IF(AND(ISNUMBER(器件参数!R6),ISNUMBER(器件参数!S6)),AND(MIN(AN5:AQ5)>=器件参数!R6,MAX(AN5:AQ5)<=器件参数!S6),TRUE),IF(AND(器件参数!E6="mixer",器件参数!U6="difference"),OR(器件参数!T6<MIN(AN5:AQ5),器件参数!T6>MAX(AN5:AQ5)),TRUE)))) -> TRUE
A7: =器件参数!A7 -> 4 | B7: =器件参数!D7 | C7: =IF(NOT(器件参数!B7),0,IF(AND(ISNUMBER(器件参数!F7),ABS(器件参数!F7)<=300),器件参数!F7,"")) -> 0 | D7: =IF(ISNUMBER(E6),E6,"") -> 20 | E7: =IF(AND(ISNUMBER(C7),ISNUMBER(D7)),C7+D7,"") -> 20 | F7: =IFERROR(IF(AND(ISNUMBER(D7)),10^(D7/10),""),"数值域错误") -> 100 | G7: =IFERROR(IF(NOT(器件参数!B7),1,IF(NOT(OR(器件参数!E7<>"mixer",AND(OR(器件参数!V7="SSB",器件参数!V7="DSB"),器件参数!W7=TRUE))),"",IF(器件参数!G7="ideal",1,IF(AND(器件参数!G7="manual",ISNUMBER(器件参数!H7),器件参数!H7>=0),10^(器件参数!H7/10),IF(AND(器件参数!G7="passive_thermal",OR(器件参数!E7="filter_bpf",器件参数!E7="filter_lpf",器件参数!E7="filter_hpf",器件参数!E7="filter_bsf",器件参数!E7="attenuator",器件参数!E7="cable",器件参数!E7="connector",器件参数!E7="switch",器件参数!E7="isolator",器件参数!E7="coupler",器件参数!E7="splitter"),AND(ISNUMBER(器件参数!F7),ABS(器件参数!F7)<=300),器件参数!F7<=0,ISNUMBER(器件参数!I7),器件参数!I7>0),1+(10^(-器件参数!F7/10)-1)*器件参数!I7/Tref_K,""))))),"数值域错误") -> 1 | H7: =IFERROR(IF(AND(ISNUMBER(H6),ISNUMBER(G7),ISNUMBER(F7)),H6+(G7-1)/F7,""),"数值域错误") -> 2.2933695 | I7: =IF(AND(ISNUMBER(H7)),10*LOG10(H7),"") -> 3.6047403 | J7: =IF(AND(ISNUMBER(Pin_dBm),ISNUMBER(D7)),Pin_dBm+D7,"") -> -10 | K7: =IF(AND(ISNUMBER(Pin_dBm),ISNUMBER(E7)),Pin_dBm+E7,"") -> -10 | L7: =IF(AND(器件参数!J7="finite",ISNUMBER(器件参数!L7),ISNUMBER(C7)),IF(器件参数!K7="input",器件参数!L7,IF(器件参数!K7="output",器件参数!L7-C7,"")),"") | M7: =IFERROR(IF(NOT(ISNUMBER(M6)),"",IF(OR(NOT(器件参数!B7),器件参数!J7="ideal"),M6,IF(AND(ISNUMBER(L7),ISNUMBER(F7)),M6+F7/10^(L7/10),""))),"数值域错误") -> 0.2 | N7: =IF(AND(ISNUMBER(M7),M7>0),-10*LOG10(M7),"") -> 6.9897 | O7: =IF(AND(ISNUMBER(N7),ISNUMBER(E7)),N7+E7,"") -> 26.9897 | P7: =IF(AND(器件参数!M7="finite",ISNUMBER(器件参数!O7),ISNUMBER(C7)),IF(器件参数!N7="input",器件参数!O7,IF(器件参数!N7="actual_output",器件参数!O7-C7+1,IF(器件参数!N7="linear_output",器件参数!O7-C7,""))),"") | Q7: =IF(器件参数!P7="",IF(AND(ISNUMBER(DefaultP),DefaultP>=1,DefaultP<=10),DefaultP,""),IF(AND(ISNUMBER(器件参数!P7),器件参数!P7>=1,器件参数!P7<=10),器件参数!P7,"")) -> 2 | R7: =IF(ISNUMBER(U6),U6,"") -> -10.000014 | S7: =IF(AND(ISNUMBER(Q7),ISNUMBER(R7),ISNUMBER(P7)),LN(10^(Q7/10)-1)+Q7*(R7-P7)*LN(10)/10,"") | T7: =IF(X7=0,0,IF(AND(X7=1,ISNUMBER(S7)),10/(Q7*LN(10))*(MAX(S7,0)+LN(1+EXP(-ABS(S7)))),"")) -> 0 | U7: =IF(AND(ISNUMBER(R7),ISNUMBER(C7),ISNUMBER(T7)),R7+C7-T7,"") -> -10.000014 | V7: =IF(AND(ISNUMBER(Pin_dBm),ISNUMBER(E7),ISNUMBER(U7)),Pin_dBm+E7-U7,"") -> 1.3970829e-05 | W7: =IF(AND(器件参数!B7,X7=1,ISNUMBER(D7)),P7-D7,"") | X7: =IF(NOT(ISNUMBER(C7)),-1,IF(OR(NOT(器件参数!B7),器件参数!M7="ideal"),0,IF(AND(ISNUMBER(P7),ISNUMBER(Q7)),1,-1))) -> 0 | Y7: =IF(ISNUMBER(H7),"有效","未知／噪声参数或口径不完整") -> 有效 | Z7: =IF(NOT(ISNUMBER(M7)),"未知／IP3参数不完整",IF(M7=0,"理想／无有限值","有效")) -> 有效 | AA7: =IF(ISNUMBER(U7),"模型估算","未知／增益或压缩参数不完整") -> 模型估算 | AB7: =IF(ISNUMBER(AC6),AC6,"") -> 100000000 | AC7: =IF(NOT(ISNUMBER(AB7)),"",IF(OR(NOT(器件参数!B7),器件参数!E7<>"mixer"),AB7,IF(AND(ISNUMBER(器件参数!T7),器件参数!T7>0),IF(器件参数!U7="sum",AB7+器件参数!T7,IF(器件参数!U7="difference",ABS(AB7-器件参数!T7),"")),""))) -> 100000000 | AD7: =IF(AND(ISNUMBER(G7)),10*LOG10(G7),"") -> 0 | AE7: =IF(AND(ISNUMBER(G7),ISNUMBER(F7)),Tref_K*(G7-1)/F7,"") -> 0 | AF7: =IF(AND(ISNUMBER(H7),ISNUMBER(E7),NoiseConfigOK),10*LOG10(Boltzmann*Bnoise_Hz*(Tsource_K+Tref_K*(H7-1)))+30+E7,"") -> -90.370447 | AG7: =IF(AND(ISNUMBER(K7),ISNUMBER(AF7)),K7-AF7,"") -> 80.370447 | AH7: =IF(AND(ToneEnabled,ISNUMBER(E7),ISNUMBER(TonePin)),TonePin+E7,"") -> -10 | AI7: =IF(AND(ToneEnabled,ISNUMBER(E7),ISNUMBER(N7),ISNUMBER(TonePin)),3*TonePin+E7-2*N7,"") -> -83.9794 | AJ7: =IF(X7=1,Q7,"") | AK7: =IF(NOT(器件参数!B7),"旁路",IF(NOT(ISNUMBER(AC7)),"频率未知",IF(AC7<=SignalBW/2,"跨零频",IF(AND(ISNUMBER(器件参数!R7),ISNUMBER(器件参数!S7)),IF(AND(AB7-SignalBW/2>=器件参数!R7,AB7+SignalBW/2<=器件参数!S7),"有效","超声明通带"),"未声明通带")))) -> 旁路 | AL7: =IFERROR(IF(AND(X7=1,ISNUMBER(D7)),10^(Q7*(D7-P7)/10),0),"数值域错误") -> 0 | AM7: =IF(AND(器件参数!B7,ISNUMBER(器件参数!X7),OR(AND(ISNUMBER(J7),J7>器件参数!X7),IF(AND(ToneEnabled,ISNUMBER(TonePin),ISNUMBER(D7)),TonePin+10*LOG10(2)+D7>器件参数!X7,FALSE))),"超过绝对最大输入额定值","") | AN7: =IF(NOT(ISNUMBER(AN6)),"",IF(OR(NOT(器件参数!B7),器件参数!E7<>"mixer"),AN6,IF(AND(ISNUMBER(器件参数!T7),器件参数!T7>0),IF(器件参数!U7="sum",AN6+器件参数!T7,ABS(AN6-器件参数!T7)),""))) -> 99950000 | AO7: =IF(NOT(ISNUMBER(AO6)),"",IF(OR(NOT(器件参数!B7),器件参数!E7<>"mixer"),AO6,IF(AND(ISNUMBER(器件参数!T7),器件参数!T7>0),IF(器件参数!U7="sum",AO6+器件参数!T7,ABS(AO6-器件参数!T7)),""))) -> 100050000 | AP7: =IF(NOT(ISNUMBER(AP6)),"",IF(OR(NOT(器件参数!B7),器件参数!E7<>"mixer"),AP6,IF(AND(ISNUMBER(器件参数!T7),器件参数!T7>0),IF(器件参数!U7="sum",AP6+器件参数!T7,ABS(AP6-器件参数!T7)),""))) -> 99850000 | AQ7: =IF(NOT(ISNUMBER(AQ6)),"",IF(OR(NOT(器件参数!B7),器件参数!E7<>"mixer"),AQ6,IF(AND(ISNUMBER(器件参数!T7),器件参数!T7>0),IF(器件参数!U7="sum",AQ6+器件参数!T7,ABS(AQ6-器件参数!T7)),""))) -> 100150000 | AR7: =IF(NOT(AR6),FALSE,IF(NOT(器件参数!B7),TRUE,AND(COUNT(AN7:AQ7)=4,MIN(AN7:AQ7)>0,IF(AND(ISNUMBER(器件参数!R7),ISNUMBER(器件参数!S7)),AND(MIN(AN6:AQ6)>=器件参数!R7,MAX(AN6:AQ6)<=器件参数!S7),TRUE),IF(AND(器件参数!E7="mixer",器件参数!U7="difference"),OR(器件参数!T7<MIN(AN6:AQ6),器件参数!T7>MAX(AN6:AQ6)),TRUE)))) -> TRUE
A8: =器件参数!A8 -> 5 | B8: =器件参数!D8 | C8: =IF(NOT(器件参数!B8),0,IF(AND(ISNUMBER(器件参数!F8),ABS(器件参数!F8)<=300),器件参数!F8,"")) -> 0 | D8: =IF(ISNUMBER(E7),E7,"") -> 20 | E8: =IF(AND(ISNUMBER(C8),ISNUMBER(D8)),C8+D8,"") -> 20 | F8: =IFERROR(IF(AND(ISNUMBER(D8)),10^(D8/10),""),"数值域错误") -> 100 | G8: =IFERROR(IF(NOT(器件参数!B8),1,IF(NOT(OR(器件参数!E8<>"mixer",AND(OR(器件参数!V8="SSB",器件参数!V8="DSB"),器件参数!W8=TRUE))),"",IF(器件参数!G8="ideal",1,IF(AND(器件参数!G8="manual",ISNUMBER(器件参数!H8),器件参数!H8>=0),10^(器件参数!H8/10),IF(AND(器件参数!G8="passive_thermal",OR(器件参数!E8="filter_bpf",器件参数!E8="filter_lpf",器件参数!E8="filter_hpf",器件参数!E8="filter_bsf",器件参数!E8="attenuator",器件参数!E8="cable",器件参数!E8="connector",器件参数!E8="switch",器件参数!E8="isolator",器件参数!E8="coupler",器件参数!E8="splitter"),AND(ISNUMBER(器件参数!F8),ABS(器件参数!F8)<=300),器件参数!F8<=0,ISNUMBER(器件参数!I8),器件参数!I8>0),1+(10^(-器件参数!F8/10)-1)*器件参数!I8/Tref_K,""))))),"数值域错误") -> 1 | H8: =IFERROR(IF(AND(ISNUMBER(H7),ISNUMBER(G8),ISNUMBER(F8)),H7+(G8-1)/F8,""),"数值域错误") -> 2.2933695 | I8: =IF(AND(ISNUMBER(H8)),10*LOG10(H8),"") -> 3.6047403 | J8: =IF(AND(ISNUMBER(Pin_dBm),ISNUMBER(D8)),Pin_dBm+D8,"") -> -10 | K8: =IF(AND(ISNUMBER(Pin_dBm),ISNUMBER(E8)),Pin_dBm+E8,"") -> -10 | L8: =IF(AND(器件参数!J8="finite",ISNUMBER(器件参数!L8),ISNUMBER(C8)),IF(器件参数!K8="input",器件参数!L8,IF(器件参数!K8="output",器件参数!L8-C8,"")),"") | M8: =IFERROR(IF(NOT(ISNUMBER(M7)),"",IF(OR(NOT(器件参数!B8),器件参数!J8="ideal"),M7,IF(AND(ISNUMBER(L8),ISNUMBER(F8)),M7+F8/10^(L8/10),""))),"数值域错误") -> 0.2 | N8: =IF(AND(ISNUMBER(M8),M8>0),-10*LOG10(M8),"") -> 6.9897 | O8: =IF(AND(ISNUMBER(N8),ISNUMBER(E8)),N8+E8,"") -> 26.9897 | P8: =IF(AND(器件参数!M8="finite",ISNUMBER(器件参数!O8),ISNUMBER(C8)),IF(器件参数!N8="input",器件参数!O8,IF(器件参数!N8="actual_output",器件参数!O8-C8+1,IF(器件参数!N8="linear_output",器件参数!O8-C8,""))),"") | Q8: =IF(器件参数!P8="",IF(AND(ISNUMBER(DefaultP),DefaultP>=1,DefaultP<=10),DefaultP,""),IF(AND(ISNUMBER(器件参数!P8),器件参数!P8>=1,器件参数!P8<=10),器件参数!P8,"")) -> 2 | R8: =IF(ISNUMBER(U7),U7,"") -> -10.000014 | S8: =IF(AND(ISNUMBER(Q8),ISNUMBER(R8),ISNUMBER(P8)),LN(10^(Q8/10)-1)+Q8*(R8-P8)*LN(10)/10,"") | T8: =IF(X8=0,0,IF(AND(X8=1,ISNUMBER(S8)),10/(Q8*LN(10))*(MAX(S8,0)+LN(1+EXP(-ABS(S8)))),"")) -> 0 | U8: =IF(AND(ISNUMBER(R8),ISNUMBER(C8),ISNUMBER(T8)),R8+C8-T8,"") -> -10.000014 | V8: =IF(AND(ISNUMBER(Pin_dBm),ISNUMBER(E8),ISNUMBER(U8)),Pin_dBm+E8-U8,"") -> 1.3970829e-05 | W8: =IF(AND(器件参数!B8,X8=1,ISNUMBER(D8)),P8-D8,"") | X8: =IF(NOT(ISNUMBER(C8)),-1,IF(OR(NOT(器件参数!B8),器件参数!M8="ideal"),0,IF(AND(ISNUMBER(P8),ISNUMBER(Q8)),1,-1))) -> 0 | Y8: =IF(ISNUMBER(H8),"有效","未知／噪声参数或口径不完整") -> 有效 | Z8: =IF(NOT(ISNUMBER(M8)),"未知／IP3参数不完整",IF(M8=0,"理想／无有限值","有效")) -> 有效 | AA8: =IF(ISNUMBER(U8),"模型估算","未知／增益或压缩参数不完整") -> 模型估算 | AB8: =IF(ISNUMBER(AC7),AC7,"") -> 100000000 | AC8: =IF(NOT(ISNUMBER(AB8)),"",IF(OR(NOT(器件参数!B8),器件参数!E8<>"mixer"),AB8,IF(AND(ISNUMBER(器件参数!T8),器件参数!T8>0),IF(器件参数!U8="sum",AB8+器件参数!T8,IF(器件参数!U8="difference",ABS(AB8-器件参数!T8),"")),""))) -> 100000000 | AD8: =IF(AND(ISNUMBER(G8)),10*LOG10(G8),"") -> 0 | AE8: =IF(AND(ISNUMBER(G8),ISNUMBER(F8)),Tref_K*(G8-1)/F8,"") -> 0 | AF8: =IF(AND(ISNUMBER(H8),ISNUMBER(E8),NoiseConfigOK),10*LOG10(Boltzmann*Bnoise_Hz*(Tsource_K+Tref_K*(H8-1)))+30+E8,"") -> -90.370447 | AG8: =IF(AND(ISNUMBER(K8),ISNUMBER(AF8)),K8-AF8,"") -> 80.370447 | AH8: =IF(AND(ToneEnabled,ISNUMBER(E8),ISNUMBER(TonePin)),TonePin+E8,"") -> -10 | AI8: =IF(AND(ToneEnabled,ISNUMBER(E8),ISNUMBER(N8),ISNUMBER(TonePin)),3*TonePin+E8-2*N8,"") -> -83.9794 | AJ8: =IF(X8=1,Q8,"") | AK8: =IF(NOT(器件参数!B8),"旁路",IF(NOT(ISNUMBER(AC8)),"频率未知",IF(AC8<=SignalBW/2,"跨零频",IF(AND(ISNUMBER(器件参数!R8),ISNUMBER(器件参数!S8)),IF(AND(AB8-SignalBW/2>=器件参数!R8,AB8+SignalBW/2<=器件参数!S8),"有效","超声明通带"),"未声明通带")))) -> 旁路 | AL8: =IFERROR(IF(AND(X8=1,ISNUMBER(D8)),10^(Q8*(D8-P8)/10),0),"数值域错误") -> 0 | AM8: =IF(AND(器件参数!B8,ISNUMBER(器件参数!X8),OR(AND(ISNUMBER(J8),J8>器件参数!X8),IF(AND(ToneEnabled,ISNUMBER(TonePin),ISNUMBER(D8)),TonePin+10*LOG10(2)+D8>器件参数!X8,FALSE))),"超过绝对最大输入额定值","") | AN8: =IF(NOT(ISNUMBER(AN7)),"",IF(OR(NOT(器件参数!B8),器件参数!E8<>"mixer"),AN7,IF(AND(ISNUMBER(器件参数!T8),器件参数!T8>0),IF(器件参数!U8="sum",AN7+器件参数!T8,ABS(AN7-器件参数!T8)),""))) -> 99950000 | AO8: =IF(NOT(ISNUMBER(AO7)),"",IF(OR(NOT(器件参数!B8),器件参数!E8<>"mixer"),AO7,IF(AND(ISNUMBER(器件参数!T8),器件参数!T8>0),IF(器件参数!U8="sum",AO7+器件参数!T8,ABS(AO7-器件参数!T8)),""))) -> 100050000 | AP8: =IF(NOT(ISNUMBER(AP7)),"",IF(OR(NOT(器件参数!B8),器件参数!E8<>"mixer"),AP7,IF(AND(ISNUMBER(器件参数!T8),器件参数!T8>0),IF(器件参数!U8="sum",AP7+器件参数!T8,ABS(AP7-器件参数!T8)),""))) -> 99850000 | AQ8: =IF(NOT(ISNUMBER(AQ7)),"",IF(OR(NOT(器件参数!B8),器件参数!E8<>"mixer"),AQ7,IF(AND(ISNUMBER(器件参数!T8),器件参数!T8>0),IF(器件参数!U8="sum",AQ7+器件参数!T8,ABS(AQ7-器件参数!T8)),""))) -> 100150000 | AR8: =IF(NOT(AR7),FALSE,IF(NOT(器件参数!B8),TRUE,AND(COUNT(AN8:AQ8)=4,MIN(AN8:AQ8)>0,IF(AND(ISNUMBER(器件参数!R8),ISNUMBER(器件参数!S8)),AND(MIN(AN7:AQ7)>=器件参数!R8,MAX(AN7:AQ7)<=器件参数!S8),TRUE),IF(AND(器件参数!E8="mixer",器件参数!U8="difference"),OR(器件参数!T8<MIN(AN7:AQ7),器件参数!T8>MAX(AN7:AQ7)),TRUE)))) -> TRUE
A9: =器件参数!A9 -> 6 | B9: =器件参数!D9 | C9: =IF(NOT(器件参数!B9),0,IF(AND(ISNUMBER(器件参数!F9),ABS(器件参数!F9)<=300),器件参数!F9,"")) -> 0 | D9: =IF(ISNUMBER(E8),E8,"") -> 20 | E9: =IF(AND(ISNUMBER(C9),ISNUMBER(D9)),C9+D9,"") -> 20 | F9: =IFERROR(IF(AND(ISNUMBER(D9)),10^(D9/10),""),"数值域错误") -> 100 | G9: =IFERROR(IF(NOT(器件参数!B9),1,IF(NOT(OR(器件参数!E9<>"mixer",AND(OR(器件参数!V9="SSB",器件参数!V9="DSB"),器件参数!W9=TRUE))),"",IF(器件参数!G9="ideal",1,IF(AND(器件参数!G9="manual",ISNUMBER(器件参数!H9),器件参数!H9>=0),10^(器件参数!H9/10),IF(AND(器件参数!G9="passive_thermal",OR(器件参数!E9="filter_bpf",器件参数!E9="filter_lpf",器件参数!E9="filter_hpf",器件参数!E9="filter_bsf",器件参数!E9="attenuator",器件参数!E9="cable",器件参数!E9="connector",器件参数!E9="switch",器件参数!E9="isolator",器件参数!E9="coupler",器件参数!E9="splitter"),AND(ISNUMBER(器件参数!F9),ABS(器件参数!F9)<=300),器件参数!F9<=0,ISNUMBER(器件参数!I9),器件参数!I9>0),1+(10^(-器件参数!F9/10)-1)*器件参数!I9/Tref_K,""))))),"数值域错误") -> 1 | H9: =IFERROR(IF(AND(ISNUMBER(H8),ISNUMBER(G9),ISNUMBER(F9)),H8+(G9-1)/F9,""),"数值域错误") -> 2.2933695 | I9: =IF(AND(ISNUMBER(H9)),10*LOG10(H9),"") -> 3.6047403 | J9: =IF(AND(ISNUMBER(Pin_dBm),ISNUMBER(D9)),Pin_dBm+D9,"") -> -10 | K9: =IF(AND(ISNUMBER(Pin_dBm),ISNUMBER(E9)),Pin_dBm+E9,"") -> -10 | L9: =IF(AND(器件参数!J9="finite",ISNUMBER(器件参数!L9),ISNUMBER(C9)),IF(器件参数!K9="input",器件参数!L9,IF(器件参数!K9="output",器件参数!L9-C9,"")),"") | M9: =IFERROR(IF(NOT(ISNUMBER(M8)),"",IF(OR(NOT(器件参数!B9),器件参数!J9="ideal"),M8,IF(AND(ISNUMBER(L9),ISNUMBER(F9)),M8+F9/10^(L9/10),""))),"数值域错误") -> 0.2 | N9: =IF(AND(ISNUMBER(M9),M9>0),-10*LOG10(M9),"") -> 6.9897 | O9: =IF(AND(ISNUMBER(N9),ISNUMBER(E9)),N9+E9,"") -> 26.9897 | P9: =IF(AND(器件参数!M9="finite",ISNUMBER(器件参数!O9),ISNUMBER(C9)),IF(器件参数!N9="input",器件参数!O9,IF(器件参数!N9="actual_output",器件参数!O9-C9+1,IF(器件参数!N9="linear_output",器件参数!O9-C9,""))),"") | Q9: =IF(器件参数!P9="",IF(AND(ISNUMBER(DefaultP),DefaultP>=1,DefaultP<=10),DefaultP,""),IF(AND(ISNUMBER(器件参数!P9),器件参数!P9>=1,器件参数!P9<=10),器件参数!P9,"")) -> 2 | R9: =IF(ISNUMBER(U8),U8,"") -> -10.000014 | S9: =IF(AND(ISNUMBER(Q9),ISNUMBER(R9),ISNUMBER(P9)),LN(10^(Q9/10)-1)+Q9*(R9-P9)*LN(10)/10,"") | T9: =IF(X9=0,0,IF(AND(X9=1,ISNUMBER(S9)),10/(Q9*LN(10))*(MAX(S9,0)+LN(1+EXP(-ABS(S9)))),"")) -> 0 | U9: =IF(AND(ISNUMBER(R9),ISNUMBER(C9),ISNUMBER(T9)),R9+C9-T9,"") -> -10.000014 | V9: =IF(AND(ISNUMBER(Pin_dBm),ISNUMBER(E9),ISNUMBER(U9)),Pin_dBm+E9-U9,"") -> 1.3970829e-05 | W9: =IF(AND(器件参数!B9,X9=1,ISNUMBER(D9)),P9-D9,"") | X9: =IF(NOT(ISNUMBER(C9)),-1,IF(OR(NOT(器件参数!B9),器件参数!M9="ideal"),0,IF(AND(ISNUMBER(P9),ISNUMBER(Q9)),1,-1))) -> 0 | Y9: =IF(ISNUMBER(H9),"有效","未知／噪声参数或口径不完整") -> 有效 | Z9: =IF(NOT(ISNUMBER(M9)),"未知／IP3参数不完整",IF(M9=0,"理想／无有限值","有效")) -> 有效 | AA9: =IF(ISNUMBER(U9),"模型估算","未知／增益或压缩参数不完整") -> 模型估算 | AB9: =IF(ISNUMBER(AC8),AC8,"") -> 100000000 | AC9: =IF(NOT(ISNUMBER(AB9)),"",IF(OR(NOT(器件参数!B9),器件参数!E9<>"mixer"),AB9,IF(AND(ISNUMBER(器件参数!T9),器件参数!T9>0),IF(器件参数!U9="sum",AB9+器件参数!T9,IF(器件参数!U9="difference",ABS(AB9-器件参数!T9),"")),""))) -> 100000000 | AD9: =IF(AND(ISNUMBER(G9)),10*LOG10(G9),"") -> 0 | AE9: =IF(AND(ISNUMBER(G9),ISNUMBER(F9)),Tref_K*(G9-1)/F9,"") -> 0 | AF9: =IF(AND(ISNUMBER(H9),ISNUMBER(E9),NoiseConfigOK),10*LOG10(Boltzmann*Bnoise_Hz*(Tsource_K+Tref_K*(H9-1)))+30+E9,"") -> -90.370447 | AG9: =IF(AND(ISNUMBER(K9),ISNUMBER(AF9)),K9-AF9,"") -> 80.370447 | AH9: =IF(AND(ToneEnabled,ISNUMBER(E9),ISNUMBER(TonePin)),TonePin+E9,"") -> -10 | AI9: =IF(AND(ToneEnabled,ISNUMBER(E9),ISNUMBER(N9),ISNUMBER(TonePin)),3*TonePin+E9-2*N9,"") -> -83.9794 | AJ9: =IF(X9=1,Q9,"") | AK9: =IF(NOT(器件参数!B9),"旁路",IF(NOT(ISNUMBER(AC9)),"频率未知",IF(AC9<=SignalBW/2,"跨零频",IF(AND(ISNUMBER(器件参数!R9),ISNUMBER(器件参数!S9)),IF(AND(AB9-SignalBW/2>=器件参数!R9,AB9+SignalBW/2<=器件参数!S9),"有效","超声明通带"),"未声明通带")))) -> 旁路 | AL9: =IFERROR(IF(AND(X9=1,ISNUMBER(D9)),10^(Q9*(D9-P9)/10),0),"数值域错误") -> 0 | AM9: =IF(AND(器件参数!B9,ISNUMBER(器件参数!X9),OR(AND(ISNUMBER(J9),J9>器件参数!X9),IF(AND(ToneEnabled,ISNUMBER(TonePin),ISNUMBER(D9)),TonePin+10*LOG10(2)+D9>器件参数!X9,FALSE))),"超过绝对最大输入额定值","") | AN9: =IF(NOT(ISNUMBER(AN8)),"",IF(OR(NOT(器件参数!B9),器件参数!E9<>"mixer"),AN8,IF(AND(ISNUMBER(器件参数!T9),器件参数!T9>0),IF(器件参数!U9="sum",AN8+器件参数!T9,ABS(AN8-器件参数!T9)),""))) -> 99950000 | AO9: =IF(NOT(ISNUMBER(AO8)),"",IF(OR(NOT(器件参数!B9),器件参数!E9<>"mixer"),AO8,IF(AND(ISNUMBER(器件参数!T9),器件参数!T9>0),IF(器件参数!U9="sum",AO8+器件参数!T9,ABS(AO8-器件参数!T9)),""))) -> 100050000 | AP9: =IF(NOT(ISNUMBER(AP8)),"",IF(OR(NOT(器件参数!B9),器件参数!E9<>"mixer"),AP8,IF(AND(ISNUMBER(器件参数!T9),器件参数!T9>0),IF(器件参数!U9="sum",AP8+器件参数!T9,ABS(AP8-器件参数!T9)),""))) -> 99850000 | AQ9: =IF(NOT(ISNUMBER(AQ8)),"",IF(OR(NOT(器件参数!B9),器件参数!E9<>"mixer"),AQ8,IF(AND(ISNUMBER(器件参数!T9),器件参数!T9>0),IF(器件参数!U9="sum",AQ8+器件参数!T9,ABS(AQ8-器件参数!T9)),""))) -> 100150000 | AR9: =IF(NOT(AR8),FALSE,IF(NOT(器件参数!B9),TRUE,AND(COUNT(AN9:AQ9)=4,MIN(AN9:AQ9)>0,IF(AND(ISNUMBER(器件参数!R9),ISNUMBER(器件参数!S9)),AND(MIN(AN8:AQ8)>=器件参数!R9,MAX(AN8:AQ8)<=器件参数!S9),TRUE),IF(AND(器件参数!E9="mixer",器件参数!U9="difference"),OR(器件参数!T9<MIN(AN8:AQ8),器件参数!T9>MAX(AN8:AQ8)),TRUE)))) -> TRUE
A10: =器件参数!A10 -> 7 | B10: =器件参数!D10 | C10: =IF(NOT(器件参数!B10),0,IF(AND(ISNUMBER(器件参数!F10),ABS(器件参数!F10)<=300),器件参数!F10,"")) -> 0 | D10: =IF(ISNUMBER(E9),E9,"") -> 20 | E10: =IF(AND(ISNUMBER(C10),ISNUMBER(D10)),C10+D10,"") -> 20 | F10: =IFERROR(IF(AND(ISNUMBER(D10)),10^(D10/10),""),"数值域错误") -> 100 | G10: =IFERROR(IF(NOT(器件参数!B10),1,IF(NOT(OR(器件参数!E10<>"mixer",AND(OR(器件参数!V10="SSB",器件参数!V10="DSB"),器件参数!W10=TRUE))),"",IF(器件参数!G10="ideal",1,IF(AND(器件参数!G10="manual",ISNUMBER(器件参数!H10),器件参数!H10>=0),10^(器件参数!H10/10),IF(AND(器件参数!G10="passive_thermal",OR(器件参数!E10="filter_bpf",器件参数!E10="filter_lpf",器件参数!E10="filter_hpf",器件参数!E10="filter_bsf",器件参数!E10="attenuator",器件参数!E10="cable",器件参数!E10="connector",器件参数!E10="switch",器件参数!E10="isolator",器件参数!E10="coupler",器件参数!E10="splitter"),AND(ISNUMBER(器件参数!F10),ABS(器件参数!F10)<=300),器件参数!F10<=0,ISNUMBER(器件参数!I10),器件参数!I10>0),1+(10^(-器件参数!F10/10)-1)*器件参数!I10/Tref_K,""))))),"数值域错误") -> 1 | H10: =IFERROR(IF(AND(ISNUMBER(H9),ISNUMBER(G10),ISNUMBER(F10)),H9+(G10-1)/F10,""),"数值域错误") -> 2.2933695 | I10: =IF(AND(ISNUMBER(H10)),10*LOG10(H10),"") -> 3.6047403 | J10: =IF(AND(ISNUMBER(Pin_dBm),ISNUMBER(D10)),Pin_dBm+D10,"") -> -10 | K10: =IF(AND(ISNUMBER(Pin_dBm),ISNUMBER(E10)),Pin_dBm+E10,"") -> -10 | L10: =IF(AND(器件参数!J10="finite",ISNUMBER(器件参数!L10),ISNUMBER(C10)),IF(器件参数!K10="input",器件参数!L10,IF(器件参数!K10="output",器件参数!L10-C10,"")),"") | M10: =IFERROR(IF(NOT(ISNUMBER(M9)),"",IF(OR(NOT(器件参数!B10),器件参数!J10="ideal"),M9,IF(AND(ISNUMBER(L10),ISNUMBER(F10)),M9+F10/10^(L10/10),""))),"数值域错误") -> 0.2 | N10: =IF(AND(ISNUMBER(M10),M10>0),-10*LOG10(M10),"") -> 6.9897 | O10: =IF(AND(ISNUMBER(N10),ISNUMBER(E10)),N10+E10,"") -> 26.9897 | P10: =IF(AND(器件参数!M10="finite",ISNUMBER(器件参数!O10),ISNUMBER(C10)),IF(器件参数!N10="input",器件参数!O10,IF(器件参数!N10="actual_output",器件参数!O10-C10+1,IF(器件参数!N10="linear_output",器件参数!O10-C10,""))),"") | Q10: =IF(器件参数!P10="",IF(AND(ISNUMBER(DefaultP),DefaultP>=1,DefaultP<=10),DefaultP,""),IF(AND(ISNUMBER(器件参数!P10),器件参数!P10>=1,器件参数!P10<=10),器件参数!P10,"")) -> 2 | R10: =IF(ISNUMBER(U9),U9,"") -> -10.000014 | S10: =IF(AND(ISNUMBER(Q10),ISNUMBER(R10),ISNUMBER(P10)),LN(10^(Q10/10)-1)+Q10*(R10-P10)*LN(10)/10,"") | T10: =IF(X10=0,0,IF(AND(X10=1,ISNUMBER(S10)),10/(Q10*LN(10))*(MAX(S10,0)+LN(1+EXP(-ABS(S10)))),"")) -> 0 | U10: =IF(AND(ISNUMBER(R10),ISNUMBER(C10),ISNUMBER(T10)),R10+C10-T10,"") -> -10.000014 | V10: =IF(AND(ISNUMBER(Pin_dBm),ISNUMBER(E10),ISNUMBER(U10)),Pin_dBm+E10-U10,"") -> 1.3970829e-05 | W10: =IF(AND(器件参数!B10,X10=1,ISNUMBER(D10)),P10-D10,"") | X10: =IF(NOT(ISNUMBER(C10)),-1,IF(OR(NOT(器件参数!B10),器件参数!M10="ideal"),0,IF(AND(ISNUMBER(P10),ISNUMBER(Q10)),1,-1))) -> 0 | Y10: =IF(ISNUMBER(H10),"有效","未知／噪声参数或口径不完整") -> 有效 | Z10: =IF(NOT(ISNUMBER(M10)),"未知／IP3参数不完整",IF(M10=0,"理想／无有限值","有效")) -> 有效 | AA10: =IF(ISNUMBER(U10),"模型估算","未知／增益或压缩参数不完整") -> 模型估算 | AB10: =IF(ISNUMBER(AC9),AC9,"") -> 100000000 | AC10: =IF(NOT(ISNUMBER(AB10)),"",IF(OR(NOT(器件参数!B10),器件参数!E10<>"mixer"),AB10,IF(AND(ISNUMBER(器件参数!T10),器件参数!T10>0),IF(器件参数!U10="sum",AB10+器件参数!T10,IF(器件参数!U10="difference",ABS(AB10-器件参数!T10),"")),""))) -> 100000000 | AD10: =IF(AND(ISNUMBER(G10)),10*LOG10(G10),"") -> 0 | AE10: =IF(AND(ISNUMBER(G10),ISNUMBER(F10)),Tref_K*(G10-1)/F10,"") -> 0 | AF10: =IF(AND(ISNUMBER(H10),ISNUMBER(E10),NoiseConfigOK),10*LOG10(Boltzmann*Bnoise_Hz*(Tsource_K+Tref_K*(H10-1)))+30+E10,"") -> -90.370447 | AG10: =IF(AND(ISNUMBER(K10),ISNUMBER(AF10)),K10-AF10,"") -> 80.370447 | AH10: =IF(AND(ToneEnabled,ISNUMBER(E10),ISNUMBER(TonePin)),TonePin+E10,"") -> -10 | AI10: =IF(AND(ToneEnabled,ISNUMBER(E10),ISNUMBER(N10),ISNUMBER(TonePin)),3*TonePin+E10-2*N10,"") -> -83.9794 | AJ10: =IF(X10=1,Q10,"") | AK10: =IF(NOT(器件参数!B10),"旁路",IF(NOT(ISNUMBER(AC10)),"频率未知",IF(AC10<=SignalBW/2,"跨零频",IF(AND(ISNUMBER(器件参数!R10),ISNUMBER(器件参数!S10)),IF(AND(AB10-SignalBW/2>=器件参数!R10,AB10+SignalBW/2<=器件参数!S10),"有效","超声明通带"),"未声明通带")))) -> 旁路 | AL10: =IFERROR(IF(AND(X10=1,ISNUMBER(D10)),10^(Q10*(D10-P10)/10),0),"数值域错误") -> 0 | AM10: =IF(AND(器件参数!B10,ISNUMBER(器件参数!X10),OR(AND(ISNUMBER(J10),J10>器件参数!X10),IF(AND(ToneEnabled,ISNUMBER(TonePin),ISNUMBER(D10)),TonePin+10*LOG10(2)+D10>器件参数!X10,FALSE))),"超过绝对最大输入额定值","") | AN10: =IF(NOT(ISNUMBER(AN9)),"",IF(OR(NOT(器件参数!B10),器件参数!E10<>"mixer"),AN9,IF(AND(ISNUMBER(器件参数!T10),器件参数!T10>0),IF(器件参数!U10="sum",AN9+器件参数!T10,ABS(AN9-器件参数!T10)),""))) -> 99950000 | AO10: =IF(NOT(ISNUMBER(AO9)),"",IF(OR(NOT(器件参数!B10),器件参数!E10<>"mixer"),AO9,IF(AND(ISNUMBER(器件参数!T10),器件参数!T10>0),IF(器件参数!U10="sum",AO9+器件参数!T10,ABS(AO9-器件参数!T10)),""))) -> 100050000 | AP10: =IF(NOT(ISNUMBER(AP9)),"",IF(OR(NOT(器件参数!B10),器件参数!E10<>"mixer"),AP9,IF(AND(ISNUMBER(器件参数!T10),器件参数!T10>0),IF(器件参数!U10="sum",AP9+器件参数!T10,ABS(AP9-器件参数!T10)),""))) -> 99850000 | AQ10: =IF(NOT(ISNUMBER(AQ9)),"",IF(OR(NOT(器件参数!B10),器件参数!E10<>"mixer"),AQ9,IF(AND(ISNUMBER(器件参数!T10),器件参数!T10>0),IF(器件参数!U10="sum",AQ9+器件参数!T10,ABS(AQ9-器件参数!T10)),""))) -> 100150000 | AR10: =IF(NOT(AR9),FALSE,IF(NOT(器件参数!B10),TRUE,AND(COUNT(AN10:AQ10)=4,MIN(AN10:AQ10)>0,IF(AND(ISNUMBER(器件参数!R10),ISNUMBER(器件参数!S10)),AND(MIN(AN9:AQ9)>=器件参数!R10,MAX(AN9:AQ9)<=器件参数!S10),TRUE),IF(AND(器件参数!E10="mixer",器件参数!U10="difference"),OR(器件参数!T10<MIN(AN9:AQ9),器件参数!T10>MAX(AN9:AQ9)),TRUE)))) -> TRUE
A11: =器件参数!A11 -> 8 | B11: =器件参数!D11 | C11: =IF(NOT(器件参数!B11),0,IF(AND(ISNUMBER(器件参数!F11),ABS(器件参数!F11)<=300),器件参数!F11,"")) -> 0 | D11: =IF(ISNUMBER(E10),E10,"") -> 20 | E11: =IF(AND(ISNUMBER(C11),ISNUMBER(D11)),C11+D11,"") -> 20 | F11: =IFERROR(IF(AND(ISNUMBER(D11)),10^(D11/10),""),"数值域错误") -> 100 | G11: =IFERROR(IF(NOT(器件参数!B11),1,IF(NOT(OR(器件参数!E11<>"mixer",AND(OR(器件参数!V11="SSB",器件参数!V11="DSB"),器件参数!W11=TRUE))),"",IF(器件参数!G11="ideal",1,IF(AND(器件参数!G11="manual",ISNUMBER(器件参数!H11),器件参数!H11>=0),10^(器件参数!H11/10),IF(AND(器件参数!G11="passive_thermal",OR(器件参数!E11="filter_bpf",器件参数!E11="filter_lpf",器件参数!E11="filter_hpf",器件参数!E11="filter_bsf",器件参数!E11="attenuator",器件参数!E11="cable",器件参数!E11="connector",器件参数!E11="switch",器件参数!E11="isolator",器件参数!E11="coupler",器件参数!E11="splitter"),AND(ISNUMBER(器件参数!F11),ABS(器件参数!F11)<=300),器件参数!F11<=0,ISNUMBER(器件参数!I11),器件参数!I11>0),1+(10^(-器件参数!F11/10)-1)*器件参数!I11/Tref_K,""))))),"数值域错误") -> 1 | H11: =IFERROR(IF(AND(ISNUMBER(H10),ISNUMBER(G11),ISNUMBER(F11)),H10+(G11-1)/F11,""),"数值域错误") -> 2.2933695 | I11: =IF(AND(ISNUMBER(H11)),10*LOG10(H11),"") -> 3.6047403 | J11: =IF(AND(ISNUMBER(Pin_dBm),ISNUMBER(D11)),Pin_dBm+D11,"") -> -10 | K11: =IF(AND(ISNUMBER(Pin_dBm),ISNUMBER(E11)),Pin_dBm+E11,"") -> -10 | L11: =IF(AND(器件参数!J11="finite",ISNUMBER(器件参数!L11),ISNUMBER(C11)),IF(器件参数!K11="input",器件参数!L11,IF(器件参数!K11="output",器件参数!L11-C11,"")),"") | M11: =IFERROR(IF(NOT(ISNUMBER(M10)),"",IF(OR(NOT(器件参数!B11),器件参数!J11="ideal"),M10,IF(AND(ISNUMBER(L11),ISNUMBER(F11)),M10+F11/10^(L11/10),""))),"数值域错误") -> 0.2 | N11: =IF(AND(ISNUMBER(M11),M11>0),-10*LOG10(M11),"") -> 6.9897 | O11: =IF(AND(ISNUMBER(N11),ISNUMBER(E11)),N11+E11,"") -> 26.9897 | P11: =IF(AND(器件参数!M11="finite",ISNUMBER(器件参数!O11),ISNUMBER(C11)),IF(器件参数!N11="input",器件参数!O11,IF(器件参数!N11="actual_output",器件参数!O11-C11+1,IF(器件参数!N11="linear_output",器件参数!O11-C11,""))),"") | Q11: =IF(器件参数!P11="",IF(AND(ISNUMBER(DefaultP),DefaultP>=1,DefaultP<=10),DefaultP,""),IF(AND(ISNUMBER(器件参数!P11),器件参数!P11>=1,器件参数!P11<=10),器件参数!P11,"")) -> 2 | R11: =IF(ISNUMBER(U10),U10,"") -> -10.000014 | S11: =IF(AND(ISNUMBER(Q11),ISNUMBER(R11),ISNUMBER(P11)),LN(10^(Q11/10)-1)+Q11*(R11-P11)*LN(10)/10,"") | T11: =IF(X11=0,0,IF(AND(X11=1,ISNUMBER(S11)),10/(Q11*LN(10))*(MAX(S11,0)+LN(1+EXP(-ABS(S11)))),"")) -> 0 | U11: =IF(AND(ISNUMBER(R11),ISNUMBER(C11),ISNUMBER(T11)),R11+C11-T11,"") -> -10.000014 | V11: =IF(AND(ISNUMBER(Pin_dBm),ISNUMBER(E11),ISNUMBER(U11)),Pin_dBm+E11-U11,"") -> 1.3970829e-05 | W11: =IF(AND(器件参数!B11,X11=1,ISNUMBER(D11)),P11-D11,"") | X11: =IF(NOT(ISNUMBER(C11)),-1,IF(OR(NOT(器件参数!B11),器件参数!M11="ideal"),0,IF(AND(ISNUMBER(P11),ISNUMBER(Q11)),1,-1))) -> 0 | Y11: =IF(ISNUMBER(H11),"有效","未知／噪声参数或口径不完整") -> 有效 | Z11: =IF(NOT(ISNUMBER(M11)),"未知／IP3参数不完整",IF(M11=0,"理想／无有限值","有效")) -> 有效 | AA11: =IF(ISNUMBER(U11),"模型估算","未知／增益或压缩参数不完整") -> 模型估算 | AB11: =IF(ISNUMBER(AC10),AC10,"") -> 100000000 | AC11: =IF(NOT(ISNUMBER(AB11)),"",IF(OR(NOT(器件参数!B11),器件参数!E11<>"mixer"),AB11,IF(AND(ISNUMBER(器件参数!T11),器件参数!T11>0),IF(器件参数!U11="sum",AB11+器件参数!T11,IF(器件参数!U11="difference",ABS(AB11-器件参数!T11),"")),""))) -> 100000000 | AD11: =IF(AND(ISNUMBER(G11)),10*LOG10(G11),"") -> 0 | AE11: =IF(AND(ISNUMBER(G11),ISNUMBER(F11)),Tref_K*(G11-1)/F11,"") -> 0 | AF11: =IF(AND(ISNUMBER(H11),ISNUMBER(E11),NoiseConfigOK),10*LOG10(Boltzmann*Bnoise_Hz*(Tsource_K+Tref_K*(H11-1)))+30+E11,"") -> -90.370447 | AG11: =IF(AND(ISNUMBER(K11),ISNUMBER(AF11)),K11-AF11,"") -> 80.370447 | AH11: =IF(AND(ToneEnabled,ISNUMBER(E11),ISNUMBER(TonePin)),TonePin+E11,"") -> -10 | AI11: =IF(AND(ToneEnabled,ISNUMBER(E11),ISNUMBER(N11),ISNUMBER(TonePin)),3*TonePin+E11-2*N11,"") -> -83.9794 | AJ11: =IF(X11=1,Q11,"") | AK11: =IF(NOT(器件参数!B11),"旁路",IF(NOT(ISNUMBER(AC11)),"频率未知",IF(AC11<=SignalBW/2,"跨零频",IF(AND(ISNUMBER(器件参数!R11),ISNUMBER(器件参数!S11)),IF(AND(AB11-SignalBW/2>=器件参数!R11,AB11+SignalBW/2<=器件参数!S11),"有效","超声明通带"),"未声明通带")))) -> 旁路 | AL11: =IFERROR(IF(AND(X11=1,ISNUMBER(D11)),10^(Q11*(D11-P11)/10),0),"数值域错误") -> 0 | AM11: =IF(AND(器件参数!B11,ISNUMBER(器件参数!X11),OR(AND(ISNUMBER(J11),J11>器件参数!X11),IF(AND(ToneEnabled,ISNUMBER(TonePin),ISNUMBER(D11)),TonePin+10*LOG10(2)+D11>器件参数!X11,FALSE))),"超过绝对最大输入额定值","") | AN11: =IF(NOT(ISNUMBER(AN10)),"",IF(OR(NOT(器件参数!B11),器件参数!E11<>"mixer"),AN10,IF(AND(ISNUMBER(器件参数!T11),器件参数!T11>0),IF(器件参数!U11="sum",AN10+器件参数!T11,ABS(AN10-器件参数!T11)),""))) -> 99950000 | AO11: =IF(NOT(ISNUMBER(AO10)),"",IF(OR(NOT(器件参数!B11),器件参数!E11<>"mixer"),AO10,IF(AND(ISNUMBER(器件参数!T11),器件参数!T11>0),IF(器件参数!U11="sum",AO10+器件参数!T11,ABS(AO10-器件参数!T11)),""))) -> 100050000 | AP11: =IF(NOT(ISNUMBER(AP10)),"",IF(OR(NOT(器件参数!B11),器件参数!E11<>"mixer"),AP10,IF(AND(ISNUMBER(器件参数!T11),器件参数!T11>0),IF(器件参数!U11="sum",AP10+器件参数!T11,ABS(AP10-器件参数!T11)),""))) -> 99850000 | AQ11: =IF(NOT(ISNUMBER(AQ10)),"",IF(OR(NOT(器件参数!B11),器件参数!E11<>"mixer"),AQ10,IF(AND(ISNUMBER(器件参数!T11),器件参数!T11>0),IF(器件参数!U11="sum",AQ10+器件参数!T11,ABS(AQ10-器件参数!T11)),""))) -> 100150000 | AR11: =IF(NOT(AR10),FALSE,IF(NOT(器件参数!B11),TRUE,AND(COUNT(AN11:AQ11)=4,MIN(AN11:AQ11)>0,IF(AND(ISNUMBER(器件参数!R11),ISNUMBER(器件参数!S11)),AND(MIN(AN10:AQ10)>=器件参数!R11,MAX(AN10:AQ10)<=器件参数!S11),TRUE),IF(AND(器件参数!E11="mixer",器件参数!U11="difference"),OR(器件参数!T11<MIN(AN10:AQ10),器件参数!T11>MAX(AN10:AQ10)),TRUE)))) -> TRUE
A12: =器件参数!A12 -> 9 | B12: =器件参数!D12 | C12: =IF(NOT(器件参数!B12),0,IF(AND(ISNUMBER(器件参数!F12),ABS(器件参数!F12)<=300),器件参数!F12,"")) -> 0 | D12: =IF(ISNUMBER(E11),E11,"") -> 20 | E12: =IF(AND(ISNUMBER(C12),ISNUMBER(D12)),C12+D12,"") -> 20 | F12: =IFERROR(IF(AND(ISNUMBER(D12)),10^(D12/10),""),"数值域错误") -> 100 | G12: =IFERROR(IF(NOT(器件参数!B12),1,IF(NOT(OR(器件参数!E12<>"mixer",AND(OR(器件参数!V12="SSB",器件参数!V12="DSB"),器件参数!W12=TRUE))),"",IF(器件参数!G12="ideal",1,IF(AND(器件参数!G12="manual",ISNUMBER(器件参数!H12),器件参数!H12>=0),10^(器件参数!H12/10),IF(AND(器件参数!G12="passive_thermal",OR(器件参数!E12="filter_bpf",器件参数!E12="filter_lpf",器件参数!E12="filter_hpf",器件参数!E12="filter_bsf",器件参数!E12="attenuator",器件参数!E12="cable",器件参数!E12="connector",器件参数!E12="switch",器件参数!E12="isolator",器件参数!E12="coupler",器件参数!E12="splitter"),AND(ISNUMBER(器件参数!F12),ABS(器件参数!F12)<=300),器件参数!F12<=0,ISNUMBER(器件参数!I12),器件参数!I12>0),1+(10^(-器件参数!F12/10)-1)*器件参数!I12/Tref_K,""))))),"数值域错误") -> 1 | H12: =IFERROR(IF(AND(ISNUMBER(H11),ISNUMBER(G12),ISNUMBER(F12)),H11+(G12-1)/F12,""),"数值域错误") -> 2.2933695 | I12: =IF(AND(ISNUMBER(H12)),10*LOG10(H12),"") -> 3.6047403 | J12: =IF(AND(ISNUMBER(Pin_dBm),ISNUMBER(D12)),Pin_dBm+D12,"") -> -10 | K12: =IF(AND(ISNUMBER(Pin_dBm),ISNUMBER(E12)),Pin_dBm+E12,"") -> -10 | L12: =IF(AND(器件参数!J12="finite",ISNUMBER(器件参数!L12),ISNUMBER(C12)),IF(器件参数!K12="input",器件参数!L12,IF(器件参数!K12="output",器件参数!L12-C12,"")),"") | M12: =IFERROR(IF(NOT(ISNUMBER(M11)),"",IF(OR(NOT(器件参数!B12),器件参数!J12="ideal"),M11,IF(AND(ISNUMBER(L12),ISNUMBER(F12)),M11+F12/10^(L12/10),""))),"数值域错误") -> 0.2 | N12: =IF(AND(ISNUMBER(M12),M12>0),-10*LOG10(M12),"") -> 6.9897 | O12: =IF(AND(ISNUMBER(N12),ISNUMBER(E12)),N12+E12,"") -> 26.9897 | P12: =IF(AND(器件参数!M12="finite",ISNUMBER(器件参数!O12),ISNUMBER(C12)),IF(器件参数!N12="input",器件参数!O12,IF(器件参数!N12="actual_output",器件参数!O12-C12+1,IF(器件参数!N12="linear_output",器件参数!O12-C12,""))),"") | Q12: =IF(器件参数!P12="",IF(AND(ISNUMBER(DefaultP),DefaultP>=1,DefaultP<=10),DefaultP,""),IF(AND(ISNUMBER(器件参数!P12),器件参数!P12>=1,器件参数!P12<=10),器件参数!P12,"")) -> 2 | R12: =IF(ISNUMBER(U11),U11,"") -> -10.000014 | S12: =IF(AND(ISNUMBER(Q12),ISNUMBER(R12),ISNUMBER(P12)),LN(10^(Q12/10)-1)+Q12*(R12-P12)*LN(10)/10,"") | T12: =IF(X12=0,0,IF(AND(X12=1,ISNUMBER(S12)),10/(Q12*LN(10))*(MAX(S12,0)+LN(1+EXP(-ABS(S12)))),"")) -> 0 | U12: =IF(AND(ISNUMBER(R12),ISNUMBER(C12),ISNUMBER(T12)),R12+C12-T12,"") -> -10.000014 | V12: =IF(AND(ISNUMBER(Pin_dBm),ISNUMBER(E12),ISNUMBER(U12)),Pin_dBm+E12-U12,"") -> 1.3970829e-05 | W12: =IF(AND(器件参数!B12,X12=1,ISNUMBER(D12)),P12-D12,"") | X12: =IF(NOT(ISNUMBER(C12)),-1,IF(OR(NOT(器件参数!B12),器件参数!M12="ideal"),0,IF(AND(ISNUMBER(P12),ISNUMBER(Q12)),1,-1))) -> 0 | Y12: =IF(ISNUMBER(H12),"有效","未知／噪声参数或口径不完整") -> 有效 | Z12: =IF(NOT(ISNUMBER(M12)),"未知／IP3参数不完整",IF(M12=0,"理想／无有限值","有效")) -> 有效 | AA12: =IF(ISNUMBER(U12),"模型估算","未知／增益或压缩参数不完整") -> 模型估算 | AB12: =IF(ISNUMBER(AC11),AC11,"") -> 100000000 | AC12: =IF(NOT(ISNUMBER(AB12)),"",IF(OR(NOT(器件参数!B12),器件参数!E12<>"mixer"),AB12,IF(AND(ISNUMBER(器件参数!T12),器件参数!T12>0),IF(器件参数!U12="sum",AB12+器件参数!T12,IF(器件参数!U12="difference",ABS(AB12-器件参数!T12),"")),""))) -> 100000000 | AD12: =IF(AND(ISNUMBER(G12)),10*LOG10(G12),"") -> 0 | AE12: =IF(AND(ISNUMBER(G12),ISNUMBER(F12)),Tref_K*(G12-1)/F12,"") -> 0 | AF12: =IF(AND(ISNUMBER(H12),ISNUMBER(E12),NoiseConfigOK),10*LOG10(Boltzmann*Bnoise_Hz*(Tsource_K+Tref_K*(H12-1)))+30+E12,"") -> -90.370447 | AG12: =IF(AND(ISNUMBER(K12),ISNUMBER(AF12)),K12-AF12,"") -> 80.370447 | AH12: =IF(AND(ToneEnabled,ISNUMBER(E12),ISNUMBER(TonePin)),TonePin+E12,"") -> -10 | AI12: =IF(AND(ToneEnabled,ISNUMBER(E12),ISNUMBER(N12),ISNUMBER(TonePin)),3*TonePin+E12-2*N12,"") -> -83.9794 | AJ12: =IF(X12=1,Q12,"") | AK12: =IF(NOT(器件参数!B12),"旁路",IF(NOT(ISNUMBER(AC12)),"频率未知",IF(AC12<=SignalBW/2,"跨零频",IF(AND(ISNUMBER(器件参数!R12),ISNUMBER(器件参数!S12)),IF(AND(AB12-SignalBW/2>=器件参数!R12,AB12+SignalBW/2<=器件参数!S12),"有效","超声明通带"),"未声明通带")))) -> 旁路 | AL12: =IFERROR(IF(AND(X12=1,ISNUMBER(D12)),10^(Q12*(D12-P12)/10),0),"数值域错误") -> 0 | AM12: =IF(AND(器件参数!B12,ISNUMBER(器件参数!X12),OR(AND(ISNUMBER(J12),J12>器件参数!X12),IF(AND(ToneEnabled,ISNUMBER(TonePin),ISNUMBER(D12)),TonePin+10*LOG10(2)+D12>器件参数!X12,FALSE))),"超过绝对最大输入额定值","") | AN12: =IF(NOT(ISNUMBER(AN11)),"",IF(OR(NOT(器件参数!B12),器件参数!E12<>"mixer"),AN11,IF(AND(ISNUMBER(器件参数!T12),器件参数!T12>0),IF(器件参数!U12="sum",AN11+器件参数!T12,ABS(AN11-器件参数!T12)),""))) -> 99950000 | AO12: =IF(NOT(ISNUMBER(AO11)),"",IF(OR(NOT(器件参数!B12),器件参数!E12<>"mixer"),AO11,IF(AND(ISNUMBER(器件参数!T12),器件参数!T12>0),IF(器件参数!U12="sum",AO11+器件参数!T12,ABS(AO11-器件参数!T12)),""))) -> 100050000 | AP12: =IF(NOT(ISNUMBER(AP11)),"",IF(OR(NOT(器件参数!B12),器件参数!E12<>"mixer"),AP11,IF(AND(ISNUMBER(器件参数!T12),器件参数!T12>0),IF(器件参数!U12="sum",AP11+器件参数!T12,ABS(AP11-器件参数!T12)),""))) -> 99850000 | AQ12: =IF(NOT(ISNUMBER(AQ11)),"",IF(OR(NOT(器件参数!B12),器件参数!E12<>"mixer"),AQ11,IF(AND(ISNUMBER(器件参数!T12),器件参数!T12>0),IF(器件参数!U12="sum",AQ11+器件参数!T12,ABS(AQ11-器件参数!T12)),""))) -> 100150000 | AR12: =IF(NOT(AR11),FALSE,IF(NOT(器件参数!B12),TRUE,AND(COUNT(AN12:AQ12)=4,MIN(AN12:AQ12)>0,IF(AND(ISNUMBER(器件参数!R12),ISNUMBER(器件参数!S12)),AND(MIN(AN11:AQ11)>=器件参数!R12,MAX(AN11:AQ11)<=器件参数!S12),TRUE),IF(AND(器件参数!E12="mixer",器件参数!U12="difference"),OR(器件参数!T12<MIN(AN11:AQ11),器件参数!T12>MAX(AN11:AQ11)),TRUE)))) -> TRUE
A13: =器件参数!A13 -> 10 | B13: =器件参数!D13 | C13: =IF(NOT(器件参数!B13),0,IF(AND(ISNUMBER(器件参数!F13),ABS(器件参数!F13)<=300),器件参数!F13,"")) -> 0 | D13: =IF(ISNUMBER(E12),E12,"") -> 20 | E13: =IF(AND(ISNUMBER(C13),ISNUMBER(D13)),C13+D13,"") -> 20 | F13: =IFERROR(IF(AND(ISNUMBER(D13)),10^(D13/10),""),"数值域错误") -> 100 | G13: =IFERROR(IF(NOT(器件参数!B13),1,IF(NOT(OR(器件参数!E13<>"mixer",AND(OR(器件参数!V13="SSB",器件参数!V13="DSB"),器件参数!W13=TRUE))),"",IF(器件参数!G13="ideal",1,IF(AND(器件参数!G13="manual",ISNUMBER(器件参数!H13),器件参数!H13>=0),10^(器件参数!H13/10),IF(AND(器件参数!G13="passive_thermal",OR(器件参数!E13="filter_bpf",器件参数!E13="filter_lpf",器件参数!E13="filter_hpf",器件参数!E13="filter_bsf",器件参数!E13="attenuator",器件参数!E13="cable",器件参数!E13="connector",器件参数!E13="switch",器件参数!E13="isolator",器件参数!E13="coupler",器件参数!E13="splitter"),AND(ISNUMBER(器件参数!F13),ABS(器件参数!F13)<=300),器件参数!F13<=0,ISNUMBER(器件参数!I13),器件参数!I13>0),1+(10^(-器件参数!F13/10)-1)*器件参数!I13/Tref_K,""))))),"数值域错误") -> 1 | H13: =IFERROR(IF(AND(ISNUMBER(H12),ISNUMBER(G13),ISNUMBER(F13)),H12+(G13-1)/F13,""),"数值域错误") -> 2.2933695 | I13: =IF(AND(ISNUMBER(H13)),10*LOG10(H13),"") -> 3.6047403 | J13: =IF(AND(ISNUMBER(Pin_dBm),ISNUMBER(D13)),Pin_dBm+D13,"") -> -10 | K13: =IF(AND(ISNUMBER(Pin_dBm),ISNUMBER(E13)),Pin_dBm+E13,"") -> -10 | L13: =IF(AND(器件参数!J13="finite",ISNUMBER(器件参数!L13),ISNUMBER(C13)),IF(器件参数!K13="input",器件参数!L13,IF(器件参数!K13="output",器件参数!L13-C13,"")),"") | M13: =IFERROR(IF(NOT(ISNUMBER(M12)),"",IF(OR(NOT(器件参数!B13),器件参数!J13="ideal"),M12,IF(AND(ISNUMBER(L13),ISNUMBER(F13)),M12+F13/10^(L13/10),""))),"数值域错误") -> 0.2 | N13: =IF(AND(ISNUMBER(M13),M13>0),-10*LOG10(M13),"") -> 6.9897 | O13: =IF(AND(ISNUMBER(N13),ISNUMBER(E13)),N13+E13,"") -> 26.9897 | P13: =IF(AND(器件参数!M13="finite",ISNUMBER(器件参数!O13),ISNUMBER(C13)),IF(器件参数!N13="input",器件参数!O13,IF(器件参数!N13="actual_output",器件参数!O13-C13+1,IF(器件参数!N13="linear_output",器件参数!O13-C13,""))),"") | Q13: =IF(器件参数!P13="",IF(AND(ISNUMBER(DefaultP),DefaultP>=1,DefaultP<=10),DefaultP,""),IF(AND(ISNUMBER(器件参数!P13),器件参数!P13>=1,器件参数!P13<=10),器件参数!P13,"")) -> 2 | R13: =IF(ISNUMBER(U12),U12,"") -> -10.000014 | S13: =IF(AND(ISNUMBER(Q13),ISNUMBER(R13),ISNUMBER(P13)),LN(10^(Q13/10)-1)+Q13*(R13-P13)*LN(10)/10,"") | T13: =IF(X13=0,0,IF(AND(X13=1,ISNUMBER(S13)),10/(Q13*LN(10))*(MAX(S13,0)+LN(1+EXP(-ABS(S13)))),"")) -> 0 | U13: =IF(AND(ISNUMBER(R13),ISNUMBER(C13),ISNUMBER(T13)),R13+C13-T13,"") -> -10.000014 | V13: =IF(AND(ISNUMBER(Pin_dBm),ISNUMBER(E13),ISNUMBER(U13)),Pin_dBm+E13-U13,"") -> 1.3970829e-05 | W13: =IF(AND(器件参数!B13,X13=1,ISNUMBER(D13)),P13-D13,"") | X13: =IF(NOT(ISNUMBER(C13)),-1,IF(OR(NOT(器件参数!B13),器件参数!M13="ideal"),0,IF(AND(ISNUMBER(P13),ISNUMBER(Q13)),1,-1))) -> 0 | Y13: =IF(ISNUMBER(H13),"有效","未知／噪声参数或口径不完整") -> 有效 | Z13: =IF(NOT(ISNUMBER(M13)),"未知／IP3参数不完整",IF(M13=0,"理想／无有限值","有效")) -> 有效 | AA13: =IF(ISNUMBER(U13),"模型估算","未知／增益或压缩参数不完整") -> 模型估算 | AB13: =IF(ISNUMBER(AC12),AC12,"") -> 100000000 | AC13: =IF(NOT(ISNUMBER(AB13)),"",IF(OR(NOT(器件参数!B13),器件参数!E13<>"mixer"),AB13,IF(AND(ISNUMBER(器件参数!T13),器件参数!T13>0),IF(器件参数!U13="sum",AB13+器件参数!T13,IF(器件参数!U13="difference",ABS(AB13-器件参数!T13),"")),""))) -> 100000000 | AD13: =IF(AND(ISNUMBER(G13)),10*LOG10(G13),"") -> 0 | AE13: =IF(AND(ISNUMBER(G13),ISNUMBER(F13)),Tref_K*(G13-1)/F13,"") -> 0 | AF13: =IF(AND(ISNUMBER(H13),ISNUMBER(E13),NoiseConfigOK),10*LOG10(Boltzmann*Bnoise_Hz*(Tsource_K+Tref_K*(H13-1)))+30+E13,"") -> -90.370447 | AG13: =IF(AND(ISNUMBER(K13),ISNUMBER(AF13)),K13-AF13,"") -> 80.370447 | AH13: =IF(AND(ToneEnabled,ISNUMBER(E13),ISNUMBER(TonePin)),TonePin+E13,"") -> -10 | AI13: =IF(AND(ToneEnabled,ISNUMBER(E13),ISNUMBER(N13),ISNUMBER(TonePin)),3*TonePin+E13-2*N13,"") -> -83.9794 | AJ13: =IF(X13=1,Q13,"") | AK13: =IF(NOT(器件参数!B13),"旁路",IF(NOT(ISNUMBER(AC13)),"频率未知",IF(AC13<=SignalBW/2,"跨零频",IF(AND(ISNUMBER(器件参数!R13),ISNUMBER(器件参数!S13)),IF(AND(AB13-SignalBW/2>=器件参数!R13,AB13+SignalBW/2<=器件参数!S13),"有效","超声明通带"),"未声明通带")))) -> 旁路 | AL13: =IFERROR(IF(AND(X13=1,ISNUMBER(D13)),10^(Q13*(D13-P13)/10),0),"数值域错误") -> 0 | AM13: =IF(AND(器件参数!B13,ISNUMBER(器件参数!X13),OR(AND(ISNUMBER(J13),J13>器件参数!X13),IF(AND(ToneEnabled,ISNUMBER(TonePin),ISNUMBER(D13)),TonePin+10*LOG10(2)+D13>器件参数!X13,FALSE))),"超过绝对最大输入额定值","") | AN13: =IF(NOT(ISNUMBER(AN12)),"",IF(OR(NOT(器件参数!B13),器件参数!E13<>"mixer"),AN12,IF(AND(ISNUMBER(器件参数!T13),器件参数!T13>0),IF(器件参数!U13="sum",AN12+器件参数!T13,ABS(AN12-器件参数!T13)),""))) -> 99950000 | AO13: =IF(NOT(ISNUMBER(AO12)),"",IF(OR(NOT(器件参数!B13),器件参数!E13<>"mixer"),AO12,IF(AND(ISNUMBER(器件参数!T13),器件参数!T13>0),IF(器件参数!U13="sum",AO12+器件参数!T13,ABS(AO12-器件参数!T13)),""))) -> 100050000 | AP13: =IF(NOT(ISNUMBER(AP12)),"",IF(OR(NOT(器件参数!B13),器件参数!E13<>"mixer"),AP12,IF(AND(ISNUMBER(器件参数!T13),器件参数!T13>0),IF(器件参数!U13="sum",AP12+器件参数!T13,ABS(AP12-器件参数!T13)),""))) -> 99850000 | AQ13: =IF(NOT(ISNUMBER(AQ12)),"",IF(OR(NOT(器件参数!B13),器件参数!E13<>"mixer"),AQ12,IF(AND(ISNUMBER(器件参数!T13),器件参数!T13>0),IF(器件参数!U13="sum",AQ12+器件参数!T13,ABS(AQ12-器件参数!T13)),""))) -> 100150000 | AR13: =IF(NOT(AR12),FALSE,IF(NOT(器件参数!B13),TRUE,AND(COUNT(AN13:AQ13)=4,MIN(AN13:AQ13)>0,IF(AND(ISNUMBER(器件参数!R13),ISNUMBER(器件参数!S13)),AND(MIN(AN12:AQ12)>=器件参数!R13,MAX(AN12:AQ12)<=器件参数!S13),TRUE),IF(AND(器件参数!E13="mixer",器件参数!U13="difference"),OR(器件参数!T13<MIN(AN12:AQ12),器件参数!T13>MAX(AN12:AQ12)),TRUE)))) -> TRUE
